Workbook
Name ReceiveType: Cus!#REF!
Name ReceiveType: OtherMaster!$A$2:$A$7
Name User: Cus!#REF!
Name User: OtherMaster!$C$2:$C$5

Sheet Data_CN
A1: Date | B1: Invoice no. | C1: Customer | D1: UPC | E1: SKU | F1: Model Name | G1: Description | H1: Qty | I1: PriceBook | J1: Vat 7% | K1: Total Price (Exclude Vat) | L1: Discount | M1: Payment | N1: Staff | O1: Kerry | P1: Remark | Q1: No.# | R1: =ROUND(SUM(K:K)+SUM(K:K)*7%,2)-R3 -> 17058 | T1: =SUM(T2:T62)-T3 -> 0
A2: 45296 | B2: 105028 | C2: A041 | D2: 4892210204080 | E2: =IFERROR(VLOOKUP(D2,ProductMaster!$A:$B,2,FALSE),"") -> 018472009 | F2: =IFERROR(VLOOKUP(D2,ProductMaster!$A:$C,3,FALSE),"") -> M18 FHX-0X0 | G2: =IFERROR(VLOOKUP($D2,ProductMaster!$A:$O,4,FALSE),"") -> สว่านโรตารี่ไร้สาย 18 โวลต์ 26 มม. SDS PLUS 3 ระบบ (เครื่องเปล่า) | H2: 1 | I2: =IFERROR(VLOOKUP(E2,ProductMaster!B:G,6,FALSE),0) -> 11951.402 | J2: =ROUND(SUM(I2*7%),2) -> 836.6 | K2: =ROUND(SUM(H2*I2),2) -> 11951.4 | M2: Transfer | N2: Cat | O2: 0 | P2: No Tax Invoice | Q2: =IF(B2=B1,Q1+1,1) -> 1 | R2: =SUMIF(B2:K500,S2,K2:K500) -> 0 | S2: 505001 | T2: =R2*1.07 -> 0
A3: 45296 | B3: 105028 | C3: A041 | D3: 4892210139313-BF | E3: =IFERROR(VLOOKUP(D3,ProductMaster!$A:$B,2,FALSE),"") -> 001997014-(BF) | F3: =IFERROR(VLOOKUP(D3,ProductMaster!$A:$C,3,FALSE),"") -> M12-18FCSA-(BF) | G3: =IFERROR(VLOOKUP($D3,ProductMaster!$A:$O,4,FALSE),"") -> แท่นชาร์จแบตเตอรี่ 12-18 โวลต์ แบบชาร์จเร็ว | H3: 1 | I3: =IFERROR(VLOOKUP(E3,ProductMaster!B:G,6,FALSE),0) -> 1766.3551 | J3: =ROUND(SUM(I3*7%),2) -> 123.64 | K3: =ROUND(SUM(H3*I3),2) -> 1766.36 | M3: Transfer | N3: Cat | O3: 0 | P3: No Tax Invoice | Q3: =IF(B3=B2,Q2+1,1) -> 2 | R3: =SUMIF(B3:K501,S3,K3:K501) -> 0 | S3: 505002 | T3: =R3*1.07 -> 0 | U3: บิล 0505002 เปิดบิลใหม่แทนบิล 0105028(ยกเลิกทั้งบิลออกใหม่) เนื่องจากลูกค้าได้แบตไปผิดรุ่น ลูกค้าเพิ่มเงิน 2,200 บาท
A4: 45296 | B4: 105028 | C4: A041 | D4: 4892210220677-BF | E4: =IFERROR(VLOOKUP(D4,ProductMaster!$A:$B,2,FALSE),"") -> 001997033-(BF) | F4: =IFERROR(VLOOKUP(D4,ProductMaster!$A:$C,3,FALSE),"") -> M12HB5-(BF) | G4: =IFERROR(VLOOKUP($D4,ProductMaster!$A:$O,4,FALSE),"") -> แบตเตอรี่ 12 โวลต์ 5.0 แอมป์อาว HIGH OUTPUT | H4: 1 | I4: =IFERROR(VLOOKUP(E4,ProductMaster!B:G,6,FALSE),0) -> 1485.9813 | J4: =ROUND(SUM(I4*7%),2) -> 104.02 | K4: =ROUND(SUM(H4*I4),2) -> 1485.98 | M4: Transfer | N4: Cat | O4: 0 | P4: No Tax Invoice | Q4: =IF(B4=B3,Q3+1,1) -> 3 | R4: =SUMIF(B4:K502,S4,K4:K502) -> 0 | S4: 505003 | T4: =R4*1.07 -> 0
A5: 45416 | B5: 405004 | C5: A091 | D5: 4892210130266-BF | E5: =IFERROR(VLOOKUP(D5,ProductMaster!$A:$B,2,FALSE),"") -> 001998232-(BF) | F5: =IFERROR(VLOOKUP(D5,ProductMaster!$A:$C,3,FALSE),"") -> M12B2ASIA-(BF) | G5: =IFERROR(VLOOKUP($D5,ProductMaster!$A:$O,4,FALSE),"") -> แบตเตอรี่ 12 โวลต์ 2.0 แอมป์อาว | H5: 1 | I5: =IFERROR(VLOOKUP(E5,ProductMaster!B:G,6,FALSE),0) -> 738.31776 | J5: =ROUND(SUM(I5*7%),2) -> 51.68 | K5: =ROUND(SUM(H5*I5),2) -> 738.32 | M5: Transfer | N5: Cat | O5: 0 | P5: No Tax Invoice | Q5: =IF(B5=B4,Q4+1,1) -> 1 | R5: =SUMIF(B5:K503,S5,K5:K503) -> 0 | S5: 505004 | T5: =R5*1.07 -> 0
E6: =IFERROR(VLOOKUP(D6,ProductMaster!$A:$B,2,FALSE),"") | F6: =IFERROR(VLOOKUP(D6,ProductMaster!$A:$C,3,FALSE),"") | G6: =IFERROR(VLOOKUP($D6,ProductMaster!$A:$O,4,FALSE),"") | I6: =IFERROR(VLOOKUP(E6,ProductMaster!B:G,6,FALSE),0) -> 0 | J6: =ROUND(SUM(I6*7%),2) -> 0 | K6: =ROUND(SUM(H6*I6),2) -> 0 | M6: Transfer | N6: Cat | O6: 0 | P6: No Tax Invoice | Q6: =IF(B6=B5,Q5+1,1) -> 1 | R6: =SUMIF(B6:K504,S6,K6:K504) -> 0 | S6: 505005 | T6: =R6*1.07 -> 0
E7: =IFERROR(VLOOKUP(D7,ProductMaster!$A:$B,2,FALSE),"") | F7: =IFERROR(VLOOKUP(D7,ProductMaster!$A:$C,3,FALSE),"") | G7: =IFERROR(VLOOKUP($D7,ProductMaster!$A:$O,4,FALSE),"") | I7: =IFERROR(VLOOKUP(E7,ProductMaster!B:G,6,FALSE),0) -> 0 | J7: =ROUND(SUM(I7*7%),2) -> 0 | K7: =ROUND(SUM(H7*I7),2) -> 0 | M7: Credit Card | N7: Cat | O7: 0 | P7: Tax Invoice | Q7: =IF(B7=B6,Q6+1,1) -> 2 | R7: =SUMIF(B7:K505,S7,K7:K505) -> 0 | S7: 505006 | T7: =R7*1.07 -> 0
E8: =IFERROR(VLOOKUP(D8,ProductMaster!$A:$B,2,FALSE),"") | F8: =IFERROR(VLOOKUP(D8,ProductMaster!$A:$C,3,FALSE),"") | G8: =IFERROR(VLOOKUP($D8,ProductMaster!$A:$O,4,FALSE),"") | I8: =IFERROR(VLOOKUP(E8,ProductMaster!B:G,6,FALSE),0) -> 0 | J8: =ROUND(SUM(I8*7%),2) -> 0 | K8: =ROUND(SUM(H8*I8),2) -> 0 | M8: Credit Card | N8: Cat | O8: 0 | P8: Tax Invoice | Q8: =IF(B8=B7,Q7+1,1) -> 3 | R8: =SUMIF(B8:K506,S8,K8:K506) -> 0 | S8: 505007 | T8: =R8*1.07 -> 0
E9: =IFERROR(VLOOKUP(D9,ProductMaster!$A:$B,2,FALSE),"") | F9: =IFERROR(VLOOKUP(D9,ProductMaster!$A:$C,3,FALSE),"") | G9: =IFERROR(VLOOKUP($D9,ProductMaster!$A:$O,4,FALSE),"") | I9: =IFERROR(VLOOKUP(E9,ProductMaster!B:G,6,FALSE),0) -> 0 | J9: =ROUND(SUM(I9*7%),2) -> 0 | K9: =ROUND(SUM(H9*I9),2) -> 0 | M9: Credit Card | N9: Cat | O9: 0 | P9: Tax Invoice | Q9: =IF(B9=B8,Q8+1,1) -> 4 | R9: =SUMIF(B9:K507,S9,K9:K507) -> 0 | S9: 505008 | T9: =R9*1.07 -> 0
E10: =IFERROR(VLOOKUP(D10,ProductMaster!$A:$B,2,FALSE),"") | F10: =IFERROR(VLOOKUP(D10,ProductMaster!$A:$C,3,FALSE),"") | G10: =IFERROR(VLOOKUP($D10,ProductMaster!$A:$O,4,FALSE),"") | I10: =IFERROR(VLOOKUP(E10,ProductMaster!B:G,6,FALSE),0) -> 0 | J10: =ROUND(SUM(I10*7%),2) -> 0 | K10: =ROUND(SUM(H10*I10),2) -> 0 | M10: Credit Card | N10: Cat | O10: 0 | P10: Tax Invoice | Q10: =IF(B10=B9,Q9+1,1) -> 5 | R10: =SUMIF(B10:K508,S10,K10:K508) -> 0 | S10: 505009 | T10: =R10*1.07 -> 0
E11: =IFERROR(VLOOKUP(D11,ProductMaster!$A:$B,2,FALSE),"") | F11: =IFERROR(VLOOKUP(D11,ProductMaster!$A:$C,3,FALSE),"") | G11: =IFERROR(VLOOKUP($D11,ProductMaster!$A:$O,4,FALSE),"") | I11: =IFERROR(VLOOKUP(E11,ProductMaster!B:G,6,FALSE),0) -> 0 | J11: =ROUND(SUM(I11*7%),2) -> 0 | K11: =ROUND(SUM(H11*I11),2) -> 0 | M11: Credit Card | N11: Cat | O11: 0 | P11: Tax Invoice | Q11: =IF(B11=B10,Q10+1,1) -> 6 | R11: =SUMIF(B11:K509,S11,K11:K509) -> 0 | S11: 505010 | T11: =R11*1.07 -> 0
E12: =IFERROR(VLOOKUP(D12,ProductMaster!$A:$B,2,FALSE),"") | F12: =IFERROR(VLOOKUP(D12,ProductMaster!$A:$C,3,FALSE),"") | G12: =IFERROR(VLOOKUP($D12,ProductMaster!$A:$O,4,FALSE),"") | I12: =IFERROR(VLOOKUP(E12,ProductMaster!B:G,6,FALSE),0) -> 0 | J12: =ROUND(SUM(I12*7%),2) -> 0 | K12: =ROUND(SUM(H12*I12),2) -> 0 | M12: Cash | N12: Cat | O12: 0 | P12: No Tax Invoice | Q12: =IF(B12=B11,Q11+1,1) -> 7 | R12: =SUMIF(B12:K510,S12,K12:K510) -> 0 | S12: 505011 | T12: =R12*1.07 -> 0
E13: =IFERROR(VLOOKUP(D13,ProductMaster!$A:$B,2,FALSE),"") | F13: =IFERROR(VLOOKUP(D13,ProductMaster!$A:$C,3,FALSE),"") | G13: =IFERROR(VLOOKUP($D13,ProductMaster!$A:$O,4,FALSE),"") | I13: =IFERROR(VLOOKUP(E13,ProductMaster!B:G,6,FALSE),0) -> 0 | J13: =ROUND(SUM(I13*7%),2) -> 0 | K13: =ROUND(SUM(H13*I13),2) -> 0 | M13: Cash | N13: Cat | O13: 0 | P13: No Tax Invoice | Q13: =IF(B13=B12,Q12+1,1) -> 8 | R13: =SUMIF(B13:K511,S13,K13:K511) -> 0 | S13: 505012 | T13: =R13*1.07 -> 0
E14: =IFERROR(VLOOKUP(D14,ProductMaster!$A:$B,2,FALSE),"") | F14: =IFERROR(VLOOKUP(D14,ProductMaster!$A:$C,3,FALSE),"") | G14: =IFERROR(VLOOKUP($D14,ProductMaster!$A:$O,4,FALSE),"") | I14: =IFERROR(VLOOKUP(E14,ProductMaster!B:G,6,FALSE),0) -> 0 | J14: =ROUND(SUM(I14*7%),2) -> 0 | K14: =ROUND(SUM(H14*I14),2) -> 0 | M14: Cash | N14: Cat | O14: 0 | P14: No Tax Invoice | Q14: =IF(B14=B13,Q13+1,1) -> 9 | R14: =SUMIF(B14:K512,S14,K14:K512) -> 0 | S14: 505013 | T14: =R14*1.07 -> 0
E15: =IFERROR(VLOOKUP(D15,ProductMaster!$A:$B,2,FALSE),"") | F15: =IFERROR(VLOOKUP(D15,ProductMaster!$A:$C,3,FALSE),"") | G15: =IFERROR(VLOOKUP($D15,ProductMaster!$A:$O,4,FALSE),"") | I15: =IFERROR(VLOOKUP(E15,ProductMaster!B:G,6,FALSE),0) -> 0 | J15: =ROUND(SUM(I15*7%),2) -> 0 | K15: =ROUND(SUM(H15*I15),2) -> 0 | M15: Cash | N15: Cat | O15: 0 | P15: No Tax Invoice | Q15: =IF(B15=B14,Q14+1,1) -> 10 | R15: =SUMIF(B15:K513,S15,K15:K513) -> 0 | S15: 505014 | T15: =R15*1.07 -> 0
E16: =IFERROR(VLOOKUP(D16,ProductMaster!$A:$B,2,FALSE),"") | F16: =IFERROR(VLOOKUP(D16,ProductMaster!$A:$C,3,FALSE),"") | G16: =IFERROR(VLOOKUP($D16,ProductMaster!$A:$O,4,FALSE),"") | I16: =IFERROR(VLOOKUP(E16,ProductMaster!B:G,6,FALSE),0) -> 0 | J16: =ROUND(SUM(I16*7%),2) -> 0 | K16: =ROUND(SUM(H16*I16),2) -> 0 | M16: Transfer | N16: Cat | O16: 0 | P16: No Tax Invoice | Q16: =IF(B16=B15,Q15+1,1) -> 11 | R16: =SUMIF(B16:K514,S16,K16:K514) -> 0 | S16: 505015 | T16: =R16*1.07 -> 0
E17: =IFERROR(VLOOKUP(D17,ProductMaster!$A:$B,2,FALSE),"") | F17: =IFERROR(VLOOKUP(D17,ProductMaster!$A:$C,3,FALSE),"") | G17: =IFERROR(VLOOKUP($D17,ProductMaster!$A:$O,4,FALSE),"") | I17: =IFERROR(VLOOKUP(E17,ProductMaster!B:G,6,FALSE),0) -> 0 | J17: =ROUND(SUM(I17*7%),2) -> 0 | K17: =ROUND(SUM(H17*I17),2) -> 0 | M17: Transfer | N17: Cat | O17: 0 | P17: No Tax Invoice | Q17: =IF(B17=B16,Q16+1,1) -> 12 | R17: =SUMIF(B17:K515,S17,K17:K515) -> 0 | S17: 505016 | T17: =R17*1.07 -> 0
... E20: =IFERROR(VLOOKUP(D20,ProductMaster!$A:$B,2,FALSE),"") | F20: =IFERROR(VLOOKUP(D20,ProductMaster!$A:$C,3,FALSE),"") | G20: =IFERROR(VLOOKUP($D20,ProductMaster!$A:$O,4,FALSE),"") | I20: =IFERROR(VLOOKUP(E20,ProductMaster!B:G,6,FALSE),0) -> 0 | J20: =ROUND(SUM(I20*7%),2) -> 0 | K20: =ROUND(SUM(H20*I20),2) -> 0 | M20: Transfer | N20: Cat | O20: 0 | P20: No Tax Invoice | Q20: =IF(B20=B19,Q19+1,1) -> 15 | R20: =SUMIF(B20:K518,S20,K20:K518) -> 0 | S20: 505019 | T20: =R20*1.07 -> 0
E21: =IFERROR(VLOOKUP(D21,ProductMaster!$A:$B,2,FALSE),"") | F21: =IFERROR(VLOOKUP(D21,ProductMaster!$A:$C,3,FALSE),"") | G21: =IFERROR(VLOOKUP($D21,ProductMaster!$A:$O,4,FALSE),"") | I21: =IFERROR(VLOOKUP(E21,ProductMaster!B:G,6,FALSE),0) -> 0 | J21: =ROUND(SUM(I21*7%),2) -> 0 | K21: =ROUND(SUM(H21*I21),2) -> 0 | M21: Transfer | N21: Cat | O21: 0 | P21: No Tax Invoice | Q21: =IF(B21=B20,Q20+1,1) -> 16 | R21: =SUMIF(B21:K519,S21,K21:K519) -> 0 | S21: 505020 | T21: =R21*1.07 -> 0 | U21: โอนรวมกับบิล 0505002 ยอด 2,288
E22: =IFERROR(VLOOKUP(D22,ProductMaster!$A:$B,2,FALSE),"") | F22: =IFERROR(VLOOKUP(D22,ProductMaster!$A:$C,3,FALSE),"") | G22: =IFERROR(VLOOKUP($D22,ProductMaster!$A:$O,4,FALSE),"") | I22: =IFERROR(VLOOKUP(E22,ProductMaster!B:G,6,FALSE),0) -> 0 | J22: =ROUND(SUM(I22*7%),2) -> 0 | K22: =ROUND(SUM(H22*I22),2) -> 0 | M22: Transfer | N22: Cat | O22: 0 | P22: No Tax Invoice | Q22: =IF(B22=B21,Q21+1,1) -> 17 | R22: =SUMIF(B22:K520,S22,K22:K520) -> 0 | S22: 505021 | T22: =R22*1.07 -> 0
E23: =IFERROR(VLOOKUP(D23,ProductMaster!$A:$B,2,FALSE),"") | F23: =IFERROR(VLOOKUP(D23,ProductMaster!$A:$C,3,FALSE),"") | G23: =IFERROR(VLOOKUP($D23,ProductMaster!$A:$O,4,FALSE),"") | I23: =IFERROR(VLOOKUP(E23,ProductMaster!B:G,6,FALSE),0) -> 0 | J23: =ROUND(SUM(I23*7%),2) -> 0 | K23: =ROUND(SUM(H23*I23),2) -> 0 | M23: Transfer | N23: Cat | O23: 0 | P23: No Tax Invoice | Q23: =IF(B23=B22,Q22+1,1) -> 18 | R23: =SUMIF(B23:K521,S23,K23:K521) -> 0 | S23: 505022 | T23: =R23*1.07 -> 0
E24: =IFERROR(VLOOKUP(D24,ProductMaster!$A:$B,2,FALSE),"") | F24: =IFERROR(VLOOKUP(D24,ProductMaster!$A:$C,3,FALSE),"") | G24: =IFERROR(VLOOKUP($D24,ProductMaster!$A:$O,4,FALSE),"") | I24: =IFERROR(VLOOKUP(E24,ProductMaster!B:G,6,FALSE),0) -> 0 | J24: =ROUND(SUM(I24*7%),2) -> 0 | K24: =ROUND(SUM(H24*I24),2) -> 0 | M24: Transfer | N24: Cat | O24: 0 | P24: No Tax Invoice | Q24: =IF(B24=B23,Q23+1,1) -> 19 | R24: =SUMIF(B24:K522,S24,K24:K522) -> 0 | S24: 505023 | T24: =R24*1.07 -> 0
E25: =IFERROR(VLOOKUP(D25,ProductMaster!$A:$B,2,FALSE),"") | F25: =IFERROR(VLOOKUP(D25,ProductMaster!$A:$C,3,FALSE),"") | G25: =IFERROR(VLOOKUP($D25,ProductMaster!$A:$O,4,FALSE),"") | I25: =IFERROR(VLOOKUP(E25,ProductMaster!B:G,6,FALSE),0) -> 0 | J25: =ROUND(SUM(I25*7%),2) -> 0 | K25: =ROUND(SUM(H25*I25),2) -> 0 | M25: Transfer | N25: Cat | O25: 0 | P25: No Tax Invoice | Q25: =IF(B25=B24,Q24+1,1) -> 20 | R25: =SUMIF(B25:K523,S25,K25:K523) -> 0 | S25: 505024 | T25: =R25*1.07 -> 0
E26: =IFERROR(VLOOKUP(D26,ProductMaster!$A:$B,2,FALSE),"") | F26: =IFERROR(VLOOKUP(D26,ProductMaster!$A:$C,3,FALSE),"") | G26: =IFERROR(VLOOKUP($D26,ProductMaster!$A:$O,4,FALSE),"") | I26: =IFERROR(VLOOKUP(E26,ProductMaster!B:G,6,FALSE),0) -> 0 | J26: =ROUND(SUM(I26*7%),2) -> 0 | K26: =ROUND(SUM(H26*I26),2) -> 0 | M26: Transfer | N26: Cat | O26: 0 | P26: No Tax Invoice | Q26: =IF(B26=B25,Q25+1,1) -> 21 | R26: =SUMIF(B26:K524,S26,K26:K524) -> 0 | S26: 505025 | T26: =R26*1.07 -> 0
E27: =IFERROR(VLOOKUP(D27,ProductMaster!$A:$B,2,FALSE),"") | F27: =IFERROR(VLOOKUP(D27,ProductMaster!$A:$C,3,FALSE),"") | G27: =IFERROR(VLOOKUP($D27,ProductMaster!$A:$O,4,FALSE),"") | I27: =IFERROR(VLOOKUP(E27,ProductMaster!B:G,6,FALSE),0) -> 0 | J27: =ROUND(SUM(I27*7%),2) -> 0 | K27: =ROUND(SUM(H27*I27),2) -> 0 | M27: Transfer | N27: Cat | O27: 0 | P27: No Tax Invoice | Q27: =IF(B27=B26,Q26+1,1) -> 22 | R27: =SUMIF(B27:K525,S27,K27:K525) -> 0 | S27: 505026 | T27: =R27*1.07 -> 0
E28: =IFERROR(VLOOKUP(D28,ProductMaster!$A:$B,2,FALSE),"") | F28: =IFERROR(VLOOKUP(D28,ProductMaster!$A:$C,3,FALSE),"") | G28: =IFERROR(VLOOKUP($D28,ProductMaster!$A:$O,4,FALSE),"") | I28: =IFERROR(VLOOKUP(E28,ProductMaster!B:G,6,FALSE),0) -> 0 | J28: =ROUND(SUM(I28*7%),2) -> 0 | K28: =ROUND(SUM(H28*I28),2) -> 0 | M28: Transfer | N28: Cat | O28: 0 | P28: No Tax Invoice | Q28: =IF(B28=B27,Q27+1,1) -> 23 | R28: =SUMIF(B28:K526,S28,K28:K526) -> 0 | S28: 505027 | T28: =R28*1.07 -> 0
E29: =IFERROR(VLOOKUP(D29,ProductMaster!$A:$B,2,FALSE),"") | F29: =IFERROR(VLOOKUP(D29,ProductMaster!$A:$C,3,FALSE),"") | G29: =IFERROR(VLOOKUP($D29,ProductMaster!$A:$O,4,FALSE),"") | I29: =IFERROR(VLOOKUP(E29,ProductMaster!B:G,6,FALSE),0) -> 0 | J29: =ROUND(SUM(I29*7%),2) -> 0 | K29: =ROUND(SUM(H29*I29),2) -> 0 | M29: Transfer | N29: Cat | O29: 0 | P29: No Tax Invoice | Q29: =IF(B29=B28,Q28+1,1) -> 24 | R29: =SUMIF(B29:K527,S29,K29:K527) -> 0 | S29: 505028 | T29: =R29*1.07 -> 0
E30: =IFERROR(VLOOKUP(D30,ProductMaster!$A:$B,2,FALSE),"") | F30: =IFERROR(VLOOKUP(D30,ProductMaster!$A:$C,3,FALSE),"") | G30: =IFERROR(VLOOKUP($D30,ProductMaster!$A:$O,4,FALSE),"") | I30: =IFERROR(VLOOKUP(E30,ProductMaster!B:G,6,FALSE),0) -> 0 | J30: =ROUND(SUM(I30*7%),2) -> 0 | K30: =ROUND(SUM(H30*I30),2) -> 0 | M30: Transfer | N30: Cat | O30: 0 | P30: No Tax Invoice | Q30: =IF(B30=B29,Q29+1,1) -> 25 | R30: =SUMIF(B30:K528,S30,K30:K528) -> 0 | S30: 505029 | T30: =R30*1.07 -> 0
E31: =IFERROR(VLOOKUP(D31,ProductMaster!$A:$B,2,FALSE),"") | F31: =IFERROR(VLOOKUP(D31,ProductMaster!$A:$C,3,FALSE),"") | G31: =IFERROR(VLOOKUP($D31,ProductMaster!$A:$O,4,FALSE),"") | I31: =IFERROR(VLOOKUP(E31,ProductMaster!B:G,6,FALSE),0) -> 0 | J31: =ROUND(SUM(I31*7%),2) -> 0 | K31: =ROUND(SUM(H31*I31),2) -> 0 | M31: Transfer | N31: Cat | O31: 0 | P31: No Tax Invoice | Q31: =IF(B31=B30,Q30+1,1) -> 26 | R31: =SUMIF(B31:K529,S31,K31:K529) -> 0 | S31: 505030 | T31: =R31*1.07 -> 0
E32: =IFERROR(VLOOKUP(D32,ProductMaster!$A:$B,2,FALSE),"") | F32: =IFERROR(VLOOKUP(D32,ProductMaster!$A:$C,3,FALSE),"") | G32: =IFERROR(VLOOKUP($D32,ProductMaster!$A:$O,4,FALSE),"") | I32: =IFERROR(VLOOKUP(E32,ProductMaster!B:G,6,FALSE),0) -> 0 | J32: =ROUND(SUM(I32*7%),2) -> 0 | K32: =ROUND(SUM(H32*I32),2) -> 0 | M32: Transfer | N32: Cat | O32: 0 | P32: No Tax Invoice | Q32: =IF(B32=B31,Q31+1,1) -> 27 | R32: =SUMIF(B32:K530,S32,K32:K530) -> 0 | S32: 505031 | T32: =R32*1.07 -> 0
E33: =IFERROR(VLOOKUP(D33,ProductMaster!$A:$B,2,FALSE),"") | F33: =IFERROR(VLOOKUP(D33,ProductMaster!$A:$C,3,FALSE),"") | G33: =IFERROR(VLOOKUP($D33,ProductMaster!$A:$O,4,FALSE),"") | I33: =IFERROR(VLOOKUP(E33,ProductMaster!B:G,6,FALSE),0) -> 0 | J33: =ROUND(SUM(I33*7%),2) -> 0 | K33: =ROUND(SUM(H33*I33),2) -> 0 | M33: Transfer | N33: Cat | O33: 0 | P33: No Tax Invoice | Q33: =IF(B33=B32,Q32+1,1) -> 28 | R33: =SUMIF(B33:K531,S33,K33:K531) -> 0 | S33: 505032 | T33: =R33*1.07 -> 0
... E45: =IFERROR(VLOOKUP(D45,ProductMaster!$A:$B,2,FALSE),"") | F45: =IFERROR(VLOOKUP(D45,ProductMaster!$A:$C,3,FALSE),"") | G45: =IFERROR(VLOOKUP($D45,ProductMaster!$A:$O,4,FALSE),"") | I45: =IFERROR(VLOOKUP(E45,ProductMaster!B:G,6,FALSE),0) -> 0 | J45: =ROUND(SUM(I45*7%),2) -> 0 | K45: =ROUND(SUM(H45*I45),2) -> 0 | M45: Transfer | N45: Cat | O45: 0 | P45: No Tax Invoice | Q45: =IF(B45=B44,Q44+1,1) -> 40 | R45: =SUMIF(B45:K543,S45,K45:K543) -> 0 | S45: 505044 | T45: =R45*1.07 -> 0
E46: =IFERROR(VLOOKUP(D46,ProductMaster!$A:$B,2,FALSE),"") | F46: =IFERROR(VLOOKUP(D46,ProductMaster!$A:$C,3,FALSE),"") | G46: =IFERROR(VLOOKUP($D46,ProductMaster!$A:$O,4,FALSE),"") | I46: =IFERROR(VLOOKUP(E46,ProductMaster!B:G,6,FALSE),0) -> 0 | J46: =ROUND(SUM(I46*7%),2) -> 0 | K46: =ROUND(SUM(H46*I46),2) -> 0 | M46: Transfer | N46: Cat | O46: 0 | P46: No Tax Invoice | Q46: =IF(B46=B45,Q45+1,1) -> 41 | R46: =SUMIF(B46:K544,S46,K46:K544) -> 0 | S46: 505045 | T46: =R46*1.07 -> 0 | W46: =+V46-V45 -> 0
E47: =IFERROR(VLOOKUP(D47,ProductMaster!$A:$B,2,FALSE),"") | F47: =IFERROR(VLOOKUP(D47,ProductMaster!$A:$C,3,FALSE),"") | G47: =IFERROR(VLOOKUP($D47,ProductMaster!$A:$O,4,FALSE),"") | I47: =IFERROR(VLOOKUP(E47,ProductMaster!B:G,6,FALSE),0) -> 0 | J47: =ROUND(SUM(I47*7%),2) -> 0 | K47: =ROUND(SUM(H47*I47),2) -> 0 | M47: Transfer | N47: Cat | O47: 0 | P47: No Tax Invoice | Q47: =IF(B47=B46,Q46+1,1) -> 42 | R47: =SUMIF(B47:K545,S47,K47:K545) -> 0 | S47: 505046 | T47: =R47*1.07 -> 0
E48: =IFERROR(VLOOKUP(D48,ProductMaster!$A:$B,2,FALSE),"") | F48: =IFERROR(VLOOKUP(D48,ProductMaster!$A:$C,3,FALSE),"") | G48: =IFERROR(VLOOKUP($D48,ProductMaster!$A:$O,4,FALSE),"") | I48: =IFERROR(VLOOKUP(E48,ProductMaster!B:G,6,FALSE),0) -> 0 | J48: =ROUND(SUM(I48*7%),2) -> 0 | K48: =ROUND(SUM(H48*I48),2) -> 0 | M48: Transfer | N48: Cat | O48: 0 | P48: No Tax Invoice | Q48: =IF(B48=B47,Q47+1,1) -> 43 | R48: =SUMIF(B48:K546,S48,K48:K546) -> 0 | S48: 505047 | T48: =R48*1.07 -> 0
E49: =IFERROR(VLOOKUP(D49,ProductMaster!$A:$B,2,FALSE),"") | F49: =IFERROR(VLOOKUP(D49,ProductMaster!$A:$C,3,FALSE),"") | G49: =IFERROR(VLOOKUP($D49,ProductMaster!$A:$O,4,FALSE),"") | I49: =IFERROR(VLOOKUP(E49,ProductMaster!B:G,6,FALSE),0) -> 0 | J49: =ROUND(SUM(I49*7%),2) -> 0 | K49: =ROUND(SUM(H49*I49),2) -> 0 | M49: Transfer | N49: Cat | O49: 0 | P49: No Tax Invoice | Q49: =IF(B49=B48,Q48+1,1) -> 44 | R49: =SUMIF(B49:K547,S49,K49:K547) -> 0 | S49: 505048 | T49: =R49*1.07 -> 0
E50: =IFERROR(VLOOKUP(D50,ProductMaster!$A:$B,2,FALSE),"") | F50: =IFERROR(VLOOKUP(D50,ProductMaster!$A:$C,3,FALSE),"") | G50: =IFERROR(VLOOKUP($D50,ProductMaster!$A:$O,4,FALSE),"") | I50: =IFERROR(VLOOKUP(E50,ProductMaster!B:G,6,FALSE),0) -> 0 | J50: =ROUND(SUM(I50*7%),2) -> 0 | K50: =ROUND(SUM(H50*I50),2) -> 0 | M50: Transfer | N50: Cat | O50: 0 | P50: No Tax Invoice | Q50: =IF(B50=B49,Q49+1,1) -> 45 | R50: =SUMIF(B50:K548,S50,K50:K548) -> 0 | S50: 505049 | T50: =R50*1.07 -> 0
E51: =IFERROR(VLOOKUP(D51,ProductMaster!$A:$B,2,FALSE),"") | F51: =IFERROR(VLOOKUP(D51,ProductMaster!$A:$C,3,FALSE),"") | G51: =IFERROR(VLOOKUP($D51,ProductMaster!$A:$O,4,FALSE),"") | I51: =IFERROR(VLOOKUP(E51,ProductMaster!B:G,6,FALSE),0) -> 0 | J51: =ROUND(SUM(I51*7%),2) -> 0 | K51: =ROUND(SUM(H51*I51),2) -> 0 | M51: Transfer | N51: Cat | O51: 0 | P51: No Tax Invoice | Q51: =IF(B51=B50,Q50+1,1) -> 46 | R51: =SUMIF(B51:K549,S51,K51:K549) -> 0 | S51: 505050 | T51: =R51*1.07 -> 0
E52: =IFERROR(VLOOKUP(D52,ProductMaster!$A:$B,2,FALSE),"") | F52: =IFERROR(VLOOKUP(D52,ProductMaster!$A:$C,3,FALSE),"") | G52: =IFERROR(VLOOKUP($D52,ProductMaster!$A:$O,4,FALSE),"") | I52: =IFERROR(VLOOKUP(E52,ProductMaster!B:G,6,FALSE),0) -> 0 | J52: =ROUND(SUM(I52*7%),2) -> 0 | K52: =ROUND(SUM(H52*I52),2) -> 0 | M52: Transfer | N52: Cat | O52: 0 | P52: No Tax Invoice | Q52: =IF(B52=B51,Q51+1,1) -> 47 | R52: =SUMIF(B52:K550,S52,K52:K550) -> 0 | S52: 505051 | T52: =R52*1.07 -> 0
E53: =IFERROR(VLOOKUP(D53,ProductMaster!$A:$B,2,FALSE),"") | F53: =IFERROR(VLOOKUP(D53,ProductMaster!$A:$C,3,FALSE),"") | G53: =IFERROR(VLOOKUP($D53,ProductMaster!$A:$O,4,FALSE),"") | I53: =IFERROR(VLOOKUP(E53,ProductMaster!B:G,6,FALSE),0) -> 0 | J53: =ROUND(SUM(I53*7%),2) -> 0 | K53: =ROUND(SUM(H53*I53),2) -> 0 | M53: Transfer | N53: Cat | O53: 0 | P53: No Tax Invoice | Q53: =IF(B53=B52,Q52+1,1) -> 48 | R53: =SUMIF(B53:K551,S53,K53:K551) -> 0 | S53: 505052 | T53: =R53*1.07 -> 0
...

Sheet Cus
A1: Code | B1: Name | C1: Address (1) | D1: Address (2) | E1: Tax ID | F1: Tel.
A2: Onetime | B2: Cash | C2: Cash | D2: - | E2: - | F2: -
A3: A001 | B3: คุณ อุทิศ บุญวัฒน์ | C3: - | E3: - | F3: -
A4: A002 | B4: คุณ สุพจน์ จัดวานิล | C4: - | E4: - | F4: 819051415
A5: A003 | B5: คุณ สัมฤทธิ์ เรืองศรี | C5: - | E5: - | F5: 879977568
A6: A004 | B6: บริษัท กรุงเทพแคนวาส จำกัด | C6: 1317 ซอยจรัญสนิทวงศ์ 13 ถนนจรัญสนิทวงศ์ แขวงวัดท่าพระ เขตบางกอกใหญ่ กรุงเทพฯ 10600 | E6: 105535053715 | F6: 28640521
A7: A005 | B7: บริษัท เค.เยนเนอรัล อีควิปเม้นท์ จำกัด สำนักงานใหญ่ | C7: 107/24-25 ถนนประชาราษฎร์ สาย 1 แขวงบางซื่อ เขตบางซื่อ กรุงเทพฯ 10800 | E7: 105559117802 | F7: 25871249
A8: A006 | B8: คุณ กุลธัช บุญบางการ | C8: 169 ซอยสบายใจ ถนนสุทธิสาร เขตห้วยขวาง แขวงสามเสนนอก กรุงเทพฯ 10310 | D8: 169 ซอยสบายใจ ถนนสุทธิสาร เขตห้วยขวาง แขวงสามเสนนอก กรุงเทพฯ 10310 | E8: - | F8: 816329099
A9: A007 | B9: คุณ กิตติพันธ์ กรรณิกาธนานนท์ | C9: - | E9: - | F9: 818203086
A10: A008 | B10: บริษัท อุตสาหกรรมแป้งเหรียญทอง จำกัด | C10: 42/7 หมู่ 1 ซอยวัดอ้อมใหญ่ ถ.เพชรเกษม ต.อ้อมใหญ่ อ.สามพราน จ.นครปฐม 73160 | E10: 735545002298 | F10: 24202432
A11: A009 | B11: คุณ อัครเดช | C11: - | D11: - | E11: - | F11: 854885769
A12: A010 | B12: คุณ อโนชา | C12: - | D12: - | E12: - | F12: 892419952
A13: A011 | B13: บริษัท ฟาโรห์ เอ็นจิเนียริ่ง จำกัด (สำนักงานใหญ่) | C13: 106/146 หมู่ที่ 4 ต.หนองหอย อ.เมืองเชียงใหม่ จ.เชียงใหม่ 50000 | D13: พรณ์ปวีฐ์ นรีรัตน์ เลขที่ 91/108 หมู่บ้านอารียาเดอะคัลเลอร์เฟส 4 หมู่ 2 ต.บ้านใหม่ อ.ปากเกร็ด จ.นนทบุรี 11120 โทร.0947181619 | E13: 655564002037 | F13: 833314309
A14: A012 | B14: คุณ ชณันภัสร์ | C14: - | D14: - | E14: - | F14: 636670556
A15: A013 | B15: คุณ แบงค์ | C15: - | D15: - | E15: - | F15: 959099974
A16: A014 | B16: คุณ อมร | C16: - | D16: - | E16: - | F16: 890433537
A17: A015 | B17: คุณ เกน | C17: - | D17: - | E17: - | F17: 984891515
A18: A016 | B18: นาย สุชาติ ห้วยนอก | C18: 32 ซ.เฉลิมพระเกียรติ ร.๙ ซอย 30 แยก 14-4 แขวงดอกไม้ เขตประเวศ กรุงเทพมหานคร 10250 | E18: 1100700616737 | F18: 870925700
A19: A017 | B19: คุณ ป๋อม | C19: - | D19: - | E19: - | F19: 814444651
A20: A018 | B20: คุณ ศุภโชค | C20: - | D20: - | E20: - | F20: 818303794
A21: A019 | B21: คุณ พงษ์ถวัช | C21: - | D21: - | E21: - | F21: 820414218
A22: A020 | B22: คุณ ถนัด | C22: 101/397 หมู่บ้านปรีชา (สาย 4) ซอย 8 ถนนพุทธมณฑล สาย 4, กระทุ่มส้ม, อ. สามพราน, จ.นครปฐม 73220 | D22: - | E22: - | F22: 851434598
A23: A021 | B23: คุณ ธนะกฤษฏิ์ เกียรติไกรเมส | C23: 19/528 ซ.นวมินทร์ 26 แยก 1 คลองกุ่ม บึงกุ่ม กทม. 10240 | D23: - | E23: - | F23: 950909969
A24: A022 | B24: คุณ ณัฐวรี | C24: - | D24: - | E24: - | F24: 905645554
A25: A023 | B25: คุณ ธวัชชัย | C25: - | D25: - | F25: 902873599
A26: A024 | B26: คุณ ศิริชัย | C26: - | D26: - | E26: - | F26: 815321017
A27: A025 | B27: คุณ ณัฐชนน พัฒนโก | C27: - | D27: - | E27: - | F27: 646396535
A28: A026 | B28: คุณ คัจฉพงษ์ เศรษฐบรมศักดิ์ | C28: - | D28: - | E28: - | F28: 814712558
A29: A027 | B29: คุณ คาวี ฆารชัย | C29: - | D29: - | E29: - | F29: 857982464
A30: A028 | B30: คุณ จริยา | C30: - | D30: - | E30: - | F30: 819040910
A31: A029 | B31: บริษัท แอบโซลูท 65 | C31: 713/4 ซอย สุขุมวิท 101 แขวงบางจาก เขตพระโขนง กรุงเทพมหานคร 10260 | D31: คุณ ณัฐนรี พันธ์ทองลาภทวี โทร. 091-795-9952 206/27 อาคารชุดพักอาศัย ชั้น 3 ถ.สุขุมวิท 64 แขวงพระโขนง เขตพระโขนง กรุงเทพมหานคร 10260 | E31: 105565066777 | F31: 925656325
A32: A030 | B32: คุณ อธิ | C32: - | D32: - | E32: - | F32: 887528799
A33: A031 | B33: คุณ ขวัญชัย อิ่มแผ่ว | C33: - | D33: - | E33: - | F33: 962454529
A34: A032 | B34: คุณ จิรชยุตม์ | C34: - | D34: - | E34: - | F34: 962454529
A35: A033 | B35: คุณ ศราวุธ | C35: - | D35: - | E35: - | F35: 971075730
A36: A034 | B36: บริษัท ซีพีอาร์ เฟอร์นิเจอร์ ไซน์ จำกัด | C36: 417/214 ซอยพิบูลอุปถัมภ์ แขวงสามเสนนอก เขตห้วยขวาง กรุงเทพมหานคร 10310 | E36: 105547145326 | F36: 944041919
A37: A035 | B37: คุณ ปริญญา | C37: - | D37: - | E37: - | F37: 625905258
A38: A036 | B38: คุณ กิตติพงษ์ | C38: - | D38: - | E38: - | F38: 815295426
A39: A037 | B39: คุณ ปกรณ์ | C39: - | D39: - | E39: - | F39: 801626994
A40: A038 | B40: คุณ สุธรณ์ | C40: - | D40: - | E40: - | F40: 818132536
...

Sheet Bill
C1: บริษัท มิลวอกี้ ทูล (ประเทศไทย) จํากัด | I1: ต้นฉบับใบเสร็จรับเงิน
C2: Milwaukee Tool (Thailand) Company Limited | I2: Original Receipt
A3: 65/116-117 ชั้น 14 อาคารชำนาญเพ็ญชาติ ถ.พระราม 9 แขวงห้วยขวาง เขตห้วยขวาง กรุงเทพฯ 10310
A4: 65/116-117 Chamnan Phenjati Building, 14th Floor,Rama 9 Road, Huaykwang District, Bangkok 10310
A5: โทรศัพท์ : 66(02) 246 1074-7 แฟกซ์ : 66(02) 246 1078
A6: เลขประจำตัวผู้เสียภาษี : 0105558005717 สำนักงานใหญ่ : Head Office | I6: สำหรับลูกค้า / Customer
A8: ชื่อลูกค้า/Customer : | C8: =VLOOKUP(J8,Cus!A:B,2,FALSE) -> บริษัท พิทักษ์ธนทรัพย์ จำกัด | G8: เลขที่/No. : | H8: 505042 | J8: =VLOOKUP(H8,Data!B:C,2,FALSE) -> A123 | K8: Total Item | L8: =COUNTIF(Data!$B:$B,Bill!$H$8) -> 4
A9: ที่อยู่/Address : | C9: =VLOOKUP(J8,Cus!A:C,3,FALSE) -> อาคาร ชุดคอนโดมิเนียมอุตสาหกรรม ไคตัค ห้องเลขที่ K 005007 ชั้นที่ 5 เลขที่ 47/315 ถนน ป๊อบปูล่า ตำบลบ้านใหม่ อำเภอปากเกร็ด จังหวัดนนทบุรี 11120 | G9: วันที่/Date : | H9: =INDEX(Data!A:A,MATCH(Bill!H8,Data!B:B,0)) -> 45417
A10: เลขประจำตัวผู้เสียภาษี/Tax ID : | C10: =VLOOKUP(J8,Cus!A:E,5,FALSE) -> 135562018801 | E10: เบอร์โทร/Telephone : | F10: =VLOOKUP(J8,Cus!A:F,6,FALSE) -> 1994585159
A12: ลำดับที่ Items | B12: รายละเอียด Description | G12: ปริมาณ Quantity | H12: ราคา / หน่วย Price per Unit | I12: จำนวนเงิน Amount
A13: =ROW(A1) -> 1 | B13: {=IFERROR(IF($L$8>=1,INDEX(Data!$E:$E,MATCH(1,(Data!$B:$B=Bill!$H$8)*(Data!$Q:$Q=Bill!$A13),0),1),0),"")} -> 076800013 | C13: =IFERROR(VLOOKUP(B13,ProductMaster!B:D,2,FALSE)," ") -> 48-22-8336 | E13: =IFERROR(VLOOKUP(B13,ProductMaster!B:D,3,FALSE)," ") -> PACKOUT Cup Holder | G13: {=IFERROR(IF($L$8>=1,INDEX(Data!$H:$H,MATCH(1,(Data!$B:$B=Bill!$H$8)*(Data!$Q:$Q=Bill!$A13),0),1),0),"")} -> 1 | H13: {=IFERROR(IF($L$8>=1,INDEX(Data!$I:$I,MATCH(1,(Data!$B:$B=Bill!$H$8)*(Data!$Q:$Q=Bill!$A13),0),1),0),"")} -> 362.61682 | I13: =IF(ISERROR(G13*H13),"",G13*H13) -> 362.61682 | J13: =H13*1.07 -> 388 | L13: =IFERROR(VLOOKUP(B13,ProductMaster_iPST_iPower[[SKU]:[ProductGroup]],4,0),"") -> Accessories | N13: Hand Tools | O13: =((SUMIF(L13:L27,N13,I13:I27))*1.07) -> 0
A14: =ROW(A2) -> 2 | B14: {=IFERROR(IF($L$8>=1,INDEX(Data!$E:$E,MATCH(1,(Data!$B:$B=Bill!$H$8)*(Data!$Q:$Q=Bill!$A14),0),1),0),"")} -> 129305990 | C14: =IFERROR(VLOOKUP(B14,ProductMaster!B:D,2,FALSE)," ") -> 48-22-8487 | E14: =IFERROR(VLOOKUP(B14,ProductMaster!B:D,3,FALSE)," ") -> PACKOUT Large Mounting Plate | G14: {=IFERROR(IF($L$8>=1,INDEX(Data!$H:$H,MATCH(1,(Data!$B:$B=Bill!$H$8)*(Data!$Q:$Q=Bill!$A14),0),1),0),"")} -> 1 | H14: {=IFERROR(IF($L$8>=1,INDEX(Data!$I:$I,MATCH(1,(Data!$B:$B=Bill!$H$8)*(Data!$Q:$Q=Bill!$A14),0),1),0),"")} -> 2138.3178 | I14: =IF(ISERROR(G14*H14),"",G14*H14) -> 2138.3178 | J14: =H14*1.07 -> 2288 | L14: =IFERROR(VLOOKUP(B14,ProductMaster_iPST_iPower[[SKU]:[ProductGroup]],4,0),"") -> Packout | N14: Accessories | O14: =((SUMIF(L13:L27,N14,I13:I27))*1.07) -> 388
A15: =ROW(A3) -> 3 | B15: {=IFERROR(IF($L$8>=1,INDEX(Data!$E:$E,MATCH(1,(Data!$B:$B=Bill!$H$8)*(Data!$Q:$Q=Bill!$A15),0),1),0),"")} -> 129305469 | C15: =IFERROR(VLOOKUP(B15,ProductMaster!B:D,2,FALSE)," ") -> 48-22-8422 | E15: =IFERROR(VLOOKUP(B15,ProductMaster!B:D,3,FALSE)," ") -> กล่องเครื่องมือคอมแพ็ค PACKOUT | G15: {=IFERROR(IF($L$8>=1,INDEX(Data!$H:$H,MATCH(1,(Data!$B:$B=Bill!$H$8)*(Data!$Q:$Q=Bill!$A15),0),1),0),"")} -> 1 | H15: {=IFERROR(IF($L$8>=1,INDEX(Data!$I:$I,MATCH(1,(Data!$B:$B=Bill!$H$8)*(Data!$Q:$Q=Bill!$A15),0),1),0),"")} -> 3540.1869 | I15: =IF(ISERROR(G15*H15),"",G15*H15) -> 3540.1869 | J15: =H15*1.07 -> 3788 | L15: =IFERROR(VLOOKUP(B15,ProductMaster_iPST_iPower[[SKU]:[ProductGroup]],4,0),"") -> Packout | N15: Sum | O15: =SUM(O13:O14) -> 388
A16: =ROW(A4) -> 4 | B16: {=IFERROR(IF($L$8>=1,INDEX(Data!$E:$E,MATCH(1,(Data!$B:$B=Bill!$H$8)*(Data!$Q:$Q=Bill!$A16),0),1),0),"")} -> 006138401 | C16: =IFERROR(VLOOKUP(B16,ProductMaster!B:D,2,FALSE)," ") -> 48-22-8392R | E16: =IFERROR(VLOOKUP(B16,ProductMaster!B:D,3,FALSE)," ") -> แก้วเก็บความเย็น PACKOUT™ ขนาด 20 ออนซ์ | G16: {=IFERROR(IF($L$8>=1,INDEX(Data!$H:$H,MATCH(1,(Data!$B:$B=Bill!$H$8)*(Data!$Q:$Q=Bill!$A16),0),1),0),"")} -> 1 | H16: {=IFERROR(IF($L$8>=1,INDEX(Data!$I:$I,MATCH(1,(Data!$B:$B=Bill!$H$8)*(Data!$Q:$Q=Bill!$A16),0),1),0),"")} -> 1110.2804 | I16: =IF(ISERROR(G16*H16),"",G16*H16) -> 1110.2804 | J16: =H16*1.07 -> 1188 | L16: =IFERROR(VLOOKUP(B16,ProductMaster_iPST_iPower[[SKU]:[ProductGroup]],4,0),"") -> Packout
A17: =ROW(B5) -> 5 | B17: {=IFERROR(IF($L$8>=1,INDEX(Data!$E:$E,MATCH(1,(Data!$B:$B=Bill!$H$8)*(Data!$Q:$Q=Bill!$A17),0),1),0),"")} | C17: =IFERROR(VLOOKUP(B17,ProductMaster!B:D,2,FALSE)," ") | E17: =IFERROR(VLOOKUP(B17,ProductMaster!B:D,3,FALSE)," ") | G17: {=IFERROR(IF($L$8>=1,INDEX(Data!$H:$H,MATCH(1,(Data!$B:$B=Bill!$H$8)*(Data!$Q:$Q=Bill!$A17),0),1),0),"")} | H17: {=IFERROR(IF($L$8>=1,INDEX(Data!$I:$I,MATCH(1,(Data!$B:$B=Bill!$H$8)*(Data!$Q:$Q=Bill!$A17),0),1),0),"")} | I17: =IF(ISERROR(G17*H17),"",G17*H17) | J17: =H17*1.07 -> #VALUE! | L17: =IFERROR(VLOOKUP(B17,ProductMaster_iPST_iPower[[SKU]:[ProductGroup]],4,0),"") | O17: 5888
A18: =ROW(B6) -> 6 | B18: {=IFERROR(IF($L$8>=1,INDEX(Data!$E:$E,MATCH(1,(Data!$B:$B=Bill!$H$8)*(Data!$Q:$Q=Bill!$A18),0),1),0),"")} | C18: =IFERROR(VLOOKUP(B18,ProductMaster!B:D,2,FALSE)," ") | E18: =IFERROR(VLOOKUP(B18,ProductMaster!B:D,3,FALSE)," ") | G18: {=IFERROR(IF($L$8>=1,INDEX(Data!$H:$H,MATCH(1,(Data!$B:$B=Bill!$H$8)*(Data!$Q:$Q=Bill!$A18),0),1),0),"")} | H18: {=IFERROR(IF($L$8>=1,INDEX(Data!$I:$I,MATCH(1,(Data!$B:$B=Bill!$H$8)*(Data!$Q:$Q=Bill!$A18),0),1),0),"")} | I18: =IF(ISERROR(G18*H18),"",G18*H18) | J18: =H18*1.07 -> #VALUE! | L18: =IFERROR(VLOOKUP(B18,ProductMaster_iPST_iPower[[SKU]:[ProductGroup]],4,0),"") | O18: =O17-O15 -> 5500
A19: =ROW(B7) -> 7 | B19: {=IFERROR(IF($L$8>=1,INDEX(Data!$E:$E,MATCH(1,(Data!$B:$B=Bill!$H$8)*(Data!$Q:$Q=Bill!$A19),0),1),0),"")} | C19: =IFERROR(VLOOKUP(B19,ProductMaster!B:D,2,FALSE)," ") | E19: =IFERROR(VLOOKUP(B19,ProductMaster!B:D,3,FALSE)," ") | G19: {=IFERROR(IF($L$8>=1,INDEX(Data!$H:$H,MATCH(1,(Data!$B:$B=Bill!$H$8)*(Data!$Q:$Q=Bill!$A19),0),1),0),"")} | H19: {=IFERROR(IF($L$8>=1,INDEX(Data!$I:$I,MATCH(1,(Data!$B:$B=Bill!$H$8)*(Data!$Q:$Q=Bill!$A19),0),1),0),"")} | I19: =IF(ISERROR(G19*H19),"",G19*H19) | J19: =H19*1.07 -> #VALUE! | L19: =IFERROR(VLOOKUP(B19,ProductMaster_iPST_iPower[[SKU]:[ProductGroup]],4,0),"")
A20: =ROW(B8) -> 8 | B20: {=IFERROR(IF($L$8>=1,INDEX(Data!$E:$E,MATCH(1,(Data!$B:$B=Bill!$H$8)*(Data!$Q:$Q=Bill!$A20),0),1),0),"")} | C20: =IFERROR(VLOOKUP(B20,ProductMaster!B:D,2,FALSE)," ") | E20: =IFERROR(VLOOKUP(B20,ProductMaster!B:D,3,FALSE)," ") | G20: {=IFERROR(IF($L$8>=1,INDEX(Data!$H:$H,MATCH(1,(Data!$B:$B=Bill!$H$8)*(Data!$Q:$Q=Bill!$A20),0),1),0),"")} | H20: {=IFERROR(IF($L$8>=1,INDEX(Data!$I:$I,MATCH(1,(Data!$B:$B=Bill!$H$8)*(Data!$Q:$Q=Bill!$A20),0),1),0),"")} | I20: =IF(ISERROR(G20*H20),"",G20*H20) | L20: =IFERROR(VLOOKUP(B20,ProductMaster_iPST_iPower[[SKU]:[ProductGroup]],4,0),"")
A21: =ROW(B9) -> 9 | B21: {=IFERROR(IF($L$8>=1,INDEX(Data!$E:$E,MATCH(1,(Data!$B:$B=Bill!$H$8)*(Data!$Q:$Q=Bill!$A21),0),1),0),"")} | C21: =IFERROR(VLOOKUP(B21,ProductMaster!B:D,2,FALSE)," ") | E21: =IFERROR(VLOOKUP(B21,ProductMaster!B:D,3,FALSE)," ") | G21: {=IFERROR(IF($L$8>=1,INDEX(Data!$H:$H,MATCH(1,(Data!$B:$B=Bill!$H$8)*(Data!$Q:$Q=Bill!$A21),0),1),0),"")} | H21: {=IFERROR(IF($L$8>=1,INDEX(Data!$I:$I,MATCH(1,(Data!$B:$B=Bill!$H$8)*(Data!$Q:$Q=Bill!$A21),0),1),0),"")} | I21: =IF(ISERROR(G21*H21),"",G21*H21) | J21: =216/2 -> 108 | L21: =IFERROR(VLOOKUP(B21,ProductMaster_iPST_iPower[[SKU]:[ProductGroup]],4,0),"")
A22: =ROW(B10) -> 10 | B22: {=IFERROR(IF($L$8>=1,INDEX(Data!$E:$E,MATCH(1,(Data!$B:$B=Bill!$H$8)*(Data!$Q:$Q=Bill!$A22),0),1),0),"")} | C22: =IFERROR(VLOOKUP(B22,ProductMaster!B:D,2,FALSE)," ") | E22: =IFERROR(VLOOKUP(B22,ProductMaster!B:D,3,FALSE)," ") | G22: {=IFERROR(IF($L$8>=1,INDEX(Data!$H:$H,MATCH(1,(Data!$B:$B=Bill!$H$8)*(Data!$Q:$Q=Bill!$A22),0),1),0),"")} | H22: {=IFERROR(IF($L$8>=1,INDEX(Data!$I:$I,MATCH(1,(Data!$B:$B=Bill!$H$8)*(Data!$Q:$Q=Bill!$A22),0),1),0),"")} | I22: =IF(ISERROR(G22*H22),"",G22*H22) | J22: =J21/1.07 -> 100.93458 | L22: =IFERROR(VLOOKUP(B22,ProductMaster_iPST_iPower[[SKU]:[ProductGroup]],4,0),"")
A23: =ROW(B11) -> 11 | B23: {=IFERROR(IF($L$8>=1,INDEX(Data!$E:$E,MATCH(1,(Data!$B:$B=Bill!$H$8)*(Data!$Q:$Q=Bill!$A23),0),1),0),"")} | C23: =IFERROR(VLOOKUP(B23,ProductMaster!B:D,2,FALSE)," ") | E23: =IFERROR(VLOOKUP(B23,ProductMaster!B:D,3,FALSE)," ") | G23: {=IFERROR(IF($L$8>=1,INDEX(Data!$H:$H,MATCH(1,(Data!$B:$B=Bill!$H$8)*(Data!$Q:$Q=Bill!$A23),0),1),0),"")} | H23: {=IFERROR(IF($L$8>=1,INDEX(Data!$I:$I,MATCH(1,(Data!$B:$B=Bill!$H$8)*(Data!$Q:$Q=Bill!$A23),0),1),0),"")} | I23: =IF(ISERROR(G23*H23),"",G23*H23) | L23: =IFERROR(VLOOKUP(B23,ProductMaster_iPST_iPower[[SKU]:[ProductGroup]],4,0),"")
A24: =ROW(B12) -> 12 | B24: {=IFERROR(IF($L$8>=1,INDEX(Data!$E:$E,MATCH(1,(Data!$B:$B=Bill!$H$8)*(Data!$Q:$Q=Bill!$A24),0),1),0),"")} | C24: =IFERROR(VLOOKUP(B24,ProductMaster!B:D,2,FALSE)," ") | E24: =IFERROR(VLOOKUP(B24,ProductMaster!B:D,3,FALSE)," ") | G24: {=IFERROR(IF($L$8>=1,INDEX(Data!$H:$H,MATCH(1,(Data!$B:$B=Bill!$H$8)*(Data!$Q:$Q=Bill!$A24),0),1),0),"")} | H24: {=IFERROR(IF($L$8>=1,INDEX(Data!$I:$I,MATCH(1,(Data!$B:$B=Bill!$H$8)*(Data!$Q:$Q=Bill!$A24),0),1),0),"")} | I24: =IF(ISERROR(G24*H24),"",G24*H24) | J24: =I24*1.07 -> #VALUE! | L24: =IFERROR(VLOOKUP(B24,ProductMaster_iPST_iPower[[SKU]:[ProductGroup]],4,0),"")
A25: =ROW(B13) -> 13 | B25: {=IFERROR(IF($L$8>=1,INDEX(Data!$E:$E,MATCH(1,(Data!$B:$B=Bill!$H$8)*(Data!$Q:$Q=Bill!$A25),0),1),0),"")} | C25: =IFERROR(VLOOKUP(B25,ProductMaster!B:D,2,FALSE)," ") | E25: =IFERROR(VLOOKUP(B25,ProductMaster!B:D,3,FALSE)," ") | G25: {=IFERROR(IF($L$8>=1,INDEX(Data!$H:$H,MATCH(1,(Data!$B:$B=Bill!$H$8)*(Data!$Q:$Q=Bill!$A25),0),1),0),"")} | H25: {=IFERROR(IF($L$8>=1,INDEX(Data!$I:$I,MATCH(1,(Data!$B:$B=Bill!$H$8)*(Data!$Q:$Q=Bill!$A25),0),1),0),"")} | I25: =IF(ISERROR(G25*H25),"",G25*H25) | L25: =IFERROR(VLOOKUP(B25,ProductMaster_iPST_iPower[[SKU]:[ProductGroup]],4,0),"")
A26: =ROW(B14) -> 14 | B26: {=IFERROR(IF($L$8>=1,INDEX(Data!$E:$E,MATCH(1,(Data!$B:$B=Bill!$H$8)*(Data!$Q:$Q=Bill!$A26),0),1),0),"")} | C26: =IFERROR(VLOOKUP(B26,ProductMaster!B:D,2,FALSE)," ") | E26: =IFERROR(VLOOKUP(B26,ProductMaster!B:D,3,FALSE)," ") | G26: {=IFERROR(IF($L$8>=1,INDEX(Data!$H:$H,MATCH(1,(Data!$B:$B=Bill!$H$8)*(Data!$Q:$Q=Bill!$A26),0),1),0),"")} | H26: {=IFERROR(IF($L$8>=1,INDEX(Data!$I:$I,MATCH(1,(Data!$B:$B=Bill!$H$8)*(Data!$Q:$Q=Bill!$A26),0),1),0),"")} | I26: =IF(ISERROR(G26*H26),"",G26*H26) | L26: =IFERROR(VLOOKUP(B26,ProductMaster_iPST_iPower[[SKU]:[ProductGroup]],4,0),"")
A27: =ROW(B15) -> 15 | B27: {=IFERROR(IF($L$8>=1,INDEX(Data!$E:$E,MATCH(1,(Data!$B:$B=Bill!$H$8)*(Data!$Q:$Q=Bill!$A27),0),1),0),"")} | C27: =IFERROR(VLOOKUP(B27,ProductMaster!B:D,2,FALSE)," ") | E27: =IFERROR(VLOOKUP(B27,ProductMaster!B:D,3,FALSE)," ") | G27: {=IFERROR(IF($L$8>=1,INDEX(Data!$H:$H,MATCH(1,(Data!$B:$B=Bill!$H$8)*(Data!$Q:$Q=Bill!$A27),0),1),0),"")} | H27: {=IFERROR(IF($L$8>=1,INDEX(Data!$I:$I,MATCH(1,(Data!$B:$B=Bill!$H$8)*(Data!$Q:$Q=Bill!$A27),0),1),0),"")} | I27: =IF(ISERROR(G27*H27),"",G27*H27) | L27: =IFERROR(VLOOKUP(B27,ProductMaster_iPST_iPower[[SKU]:[ProductGroup]],4,0),"")
A29: หมายเหตุ : | C29: =_xlfn.IFS(O15>5888,"สิทธิรับฟรี กระเป๋าช่างไฟฟ้า จำนวน 1 ชิ้น",O15>2888,"สิทธิรับฟรี มีดคัทเตอร์ขนาดพกพา จำนวน 1 ชิ้น",TRUE,"") | G29: จำนวนเงินรวม / Total Amount | I29: =ROUND(SUM(I13:I28),2) -> 7151.4 | K29: =SUMIF(Data!B:B,Bill!H8,Data!K:K) -> 7151.41 | L29: =I29-K29 -> -0.01
A30: รับประกันสินค้าตามเงื่อนไขของผู้ผลิต ไม่รับเปลี่ยนหรือคืนสินค้า เว้นแต่กรณีที่สินค้าชำรุดเนื่องมาจากความบกพร่องของตัวสินค้าเอง | G30: ภาษีมูลค่าเพิ่ม / Vat 7% | I30: =ROUND(I29*0.07,2) -> 500.6
A31: ชำระโดย : | C31: =INDEX(Data!M:M,MATCH(Bill!H8,Data!B:B,0)) -> Transfer | G31: จำนวนเงินรวมทั้งสิ้น / Grand Total | I31: =ROUND(SUM(I29:I30),2) -> 7652 | Q31: =256-300 -> -44
G32: จำนวนส่วนลด / Discount
A33: บาท / Baht | C33: =BAHTTEXT(I33) -> เจ็ดพันหกร้อยห้าสิบสองบาทถ้วน | G33: จำนวนเงินรวมสุทธิ / Total Net | I33: =ROUND(I31-I32,2) -> 7652 | O33: =500-308 -> 192
C35: *** | D35: =VLOOKUP(H8,Data!B:P,15,FALSE) -> Tax Invoice
G36: ผู้รับเงิน / Received by
C38: บริษัท มิลวอกี้ ทูล (ประเทศไทย) จํากัด | I38: สำเนาใบเสร็จรับเงิน
C39: Milwaukee Tool (Thailand) Company Limited | I39: Copy Receipt
A40: 65/116-117 ชั้น 14 อาคารชำนาญเพ็ญชาติ ถ.พระราม 9 แขวงห้วยขวาง เขตห้วยขวาง กรุงเทพฯ 10310
A41: 65/116-117 Chamnan Phenjati Building, 14th Floor,Rama 9 Road, Huaykwang District, Bangkok 10310
A42: โทรศัพท์ : 66(02) 246 1074-7 แฟกซ์ : 66(02) 246 1078
A43: เลขประจำตัวผู้เสียภาษี : 0105558005717 สำนักงานใหญ่ : Head Office | I43: สำหรับบริษัท / Company
A45: ชื่อลูกค้า/Customer : | C45: =C8 -> บริษัท พิทักษ์ธนทรัพย์ จำกัด | G45: เลขที่/No. : | H45: =H8 -> 505042
A46: ที่อยู่/Address : | C46: =C9 -> อาคาร ชุดคอนโดมิเนียมอุตสาหกรรม ไคตัค ห้องเลขที่ K 005007 ชั้นที่ 5 เลขที่ 47/315 ถนน ป๊อบปูล่า ตำบลบ้านใหม่ อำเภอปากเกร็ด จังหวัดนนทบุรี 11120 | G46: วันที่/Date : | H46: =H9 -> 45417
...

Sheet Data
A1: Date | B1: Invoice no. | C1: Customer | D1: UPC | E1: SKU | F1: Model Name | G1: Description | H1: Qty | I1: PriceBook | J1: Vat 7% | K1: Total Price (Exclude Vat) | L1: Discount | M1: Payment | N1: Staff | O1: Kerry | P1: Remark | Q1: No.# | R1: =ROUND(SUM(K:K)+SUM(K:K)*7%,2)-R3 -> 549573.19 | S1: =ROUND(SUM(K:K),2)-R3 -> 512444.92 | T1: =SUM(T2:T76)-T3 -> 548316.06 | U1: =S1*7% -> 35871.144
A2: 45417 | B2: 505001 | C2: A105 | D2: 4892210222503 | E2: =IFERROR(VLOOKUP(D2,ProductMaster!$A:$B,2,FALSE),"") -> 018655011 | F2: =IFERROR(VLOOKUP(D2,ProductMaster!$A:$C,3,FALSE),"") -> M18 F2BL-0 | G2: =IFERROR(VLOOKUP($D2,ProductMaster!$A:$O,4,FALSE),"") -> เครื่องเป่าใบไม้ไร้สาย 18 โวลต์ ระบบแบตเตอรี่คู่ (เครื่องเปล่า) | H2: 1 | I2: =IFERROR(VLOOKUP(E2,ProductMaster!B:G,6,FALSE),0) -> 9241.1215 | J2: =ROUND(SUM(I2*7%),2) -> 646.88 | K2: =ROUND(SUM(H2*I2),2) -> 9241.12 | M2: Transfer | N2: Cat | O2: 0 | P2: No Tax Invoice | Q2: =IF(B2=B1,Q1+1,1) -> 1 | R2: =SUMIF($B$2:$K$500,S2,$K$2:$K$500) -> 9241.12 | S2: 505001 | T2: =R2*1.07 -> 9887.9984
A3: 45417 | B3: 505002 | C3: A041 | D3: 4892210204080 | E3: =IFERROR(VLOOKUP(D3,ProductMaster!$A:$B,2,FALSE),"") -> 018472009 | F3: =IFERROR(VLOOKUP(D3,ProductMaster!$A:$C,3,FALSE),"") -> M18 FHX-0X0 | G3: =IFERROR(VLOOKUP($D3,ProductMaster!$A:$O,4,FALSE),"") -> สว่านโรตารี่ไร้สาย 18 โวลต์ 26 มม. SDS PLUS 3 ระบบ (เครื่องเปล่า) | H3: 1 | I3: =IFERROR(VLOOKUP(E3,ProductMaster!B:G,6,FALSE),0) -> 11951.402 | J3: =ROUND(SUM(I3*7%),2) -> 836.6 | K3: =ROUND(SUM(H3*I3),2) -> 11951.4 | M3: Transfer | N3: Cat | O3: 0 | P3: Tax Invoice | Q3: =IF(B3=B2,Q2+1,1) -> 1 | R3: =SUMIF($B$2:$K$500,S3,$K$2:$K$500) -> 17958.89 | S3: 505002 | T3: =R3*1.07 -> 19216.012 | U3: บิล 0505002 เปิดบิลใหม่แทนบิล 0105028(ยกเลิกทั้งบิลออกใหม่) เนื่องจากลูกค้าได้แบตไปผิดรุ่น ลูกค้าเพิ่มเงิน 2,200 บาท
A4: 45417 | B4: 505002 | C4: A041 | D4: 4892210139313-BF | E4: =IFERROR(VLOOKUP(D4,ProductMaster!$A:$B,2,FALSE),"") -> 001997014-(BF) | F4: =IFERROR(VLOOKUP(D4,ProductMaster!$A:$C,3,FALSE),"") -> M12-18FCSA-(BF) | G4: =IFERROR(VLOOKUP($D4,ProductMaster!$A:$O,4,FALSE),"") -> แท่นชาร์จแบตเตอรี่ 12-18 โวลต์ แบบชาร์จเร็ว | H4: 1 | I4: =IFERROR(VLOOKUP(E4,ProductMaster!B:G,6,FALSE),0) -> 1766.3551 | J4: =ROUND(SUM(I4*7%),2) -> 123.64 | K4: =ROUND(SUM(H4*I4),2) -> 1766.36 | M4: Transfer | N4: Cat | O4: 0 | P4: Tax Invoice | Q4: =IF(B4=B3,Q3+1,1) -> 2 | R4: =SUMIF($B$2:$K$500,S4,$K$2:$K$500) -> 8493.46 | S4: 505003 | T4: =R4*1.07 -> 9088.0022
A5: 45417 | B5: 505002 | C5: A041 | D5: 4892210180988-BF | E5: =IFERROR(VLOOKUP(D5,ProductMaster!$A:$B,2,FALSE),"") -> 001998236DG9-(BF) | F5: =IFERROR(VLOOKUP(D5,ProductMaster!$A:$C,3,FALSE),"") -> M18HB8ASIA-(BF) | G5: =IFERROR(VLOOKUP($D5,ProductMaster!$A:$O,4,FALSE),"") -> แบตเตอรี่ 18 โวลต์ 8.0 แอมป์อาว HIGH OUTPUT | H5: 1 | I5: =IFERROR(VLOOKUP(E5,ProductMaster!B:G,6,FALSE),0) -> 3542.0561 | J5: =ROUND(SUM(I5*7%),2) -> 247.94 | K5: =ROUND(SUM(H5*I5),2) -> 3542.06 | M5: Transfer | N5: Cat | O5: 0 | P5: Tax Invoice | Q5: =IF(B5=B4,Q4+1,1) -> 3 | R5: =SUMIF($B$2:$K$500,S5,$K$2:$K$500) -> 27444.87 | S5: 505004 | T5: =R5*1.07 -> 29366.011
A6: 45417 | B6: 505002 | C6: A041 | D6: 45242573912 | E6: =IFERROR(VLOOKUP(D6,ProductMaster!$A:$B,2,FALSE),"") -> 006105507 | F6: =IFERROR(VLOOKUP(D6,ProductMaster!$A:$C,3,FALSE),"") -> 48-22-1505 | G6: =IFERROR(VLOOKUP($D6,ProductMaster!$A:$O,4,FALSE),"") -> มีดพับอเนกประสงค์ พร้อมช่องเก็บใบมีด รุ่น FASTBACK™ 6 IN 1 | H6: 1 | I6: =IFERROR(VLOOKUP(E6,ProductMaster!B:G,6,FALSE),0) -> 699.06542 | J6: =ROUND(SUM(I6*7%),2) -> 48.93 | K6: =ROUND(SUM(H6*I6),2) -> 699.07 | M6: Transfer | N6: Cat | O6: 0 | P6: Tax Invoice | Q6: =IF(B6=B5,Q5+1,1) -> 4 | R6: =SUMIF($B$2:$K$500,S6,$K$2:$K$500) -> 6624.3 | S6: 505005 | T6: =R6*1.07 -> 7088.001
A7: 45417 | B7: 505003 | C7: A107 | D7: 4892210179524 | E7: =IFERROR(VLOOKUP(D7,ProductMaster!$A:$B,2,FALSE),"") -> 018080020 | F7: =IFERROR(VLOOKUP(D7,ProductMaster!$A:$C,3,FALSE),"") -> M18 GG-0 ASIA | G7: =IFERROR(VLOOKUP($D7,ProductMaster!$A:$O,4,FALSE),"") -> M18 เครื่องอัดจารบี | H7: 1 | I7: =IFERROR(VLOOKUP(E7,ProductMaster!B:G,6,FALSE),0) -> 8493.4579 | J7: =ROUND(SUM(I7*7%),2) -> 594.54 | K7: =ROUND(SUM(H7*I7),2) -> 8493.46 | M7: Credit Card | N7: Cat | O7: 0 | P7: Tax Invoice | Q7: =IF(B7=B6,Q6+1,1) -> 1 | R7: =SUMIF($B$2:$K$500,S7,$K$2:$K$500) -> 239.25 | S7: 505006 | T7: =R7*1.07 -> 255.9975
A8: 45417 | B8: 505004 | C8: A106 | D8: 4892210240033 | E8: =IFERROR(VLOOKUP(D8,ProductMaster!$A:$B,2,FALSE),"") -> 059600307 | F8: =IFERROR(VLOOKUP(D8,ProductMaster!$A:$C,3,FALSE),"") -> M18 FPP2AC3-502LR SA | G8: =IFERROR(VLOOKUP($D8,ProductMaster!$A:$O,4,FALSE),"") -> M18 FPP2AC3-502LR SA (ชุดคอมโบสำหรับช่างไฟ) | H8: 1 | I8: =IFERROR(VLOOKUP(E8,ProductMaster!B:G,6,FALSE),0) -> 17652.336 | J8: =ROUND(SUM(I8*7%),2) -> 1235.66 | K8: =ROUND(SUM(H8*I8),2) -> 17652.34 | L8: 2000 | M8: Credit Card | N8: Cat | O8: 0 | P8: Tax Invoice | Q8: =IF(B8=B7,Q7+1,1) -> 1 | R8: =SUMIF($B$2:$K$500,S8,$K$2:$K$500) -> 856.08 | S8: 505007 | T8: =R8*1.07 -> 916.0056
A9: 45417 | B9: 505004 | C9: A106 | D9: 4892210163752 | E9: =IFERROR(VLOOKUP(D9,ProductMaster!$A:$B,2,FALSE),"") -> 018262012 | F9: =IFERROR(VLOOKUP(D9,ProductMaster!$A:$C,3,FALSE),"") -> M18 FHZ-0 | G9: =IFERROR(VLOOKUP($D9,ProductMaster!$A:$O,4,FALSE),"") -> เลื่อยชักอเนกประสงค์ไร้สาย 18 โวลต์ (เครื่องเปล่า) | H9: 1 | I9: =IFERROR(VLOOKUP(E9,ProductMaster!B:G,6,FALSE),0) -> 6250.4673 | J9: =ROUND(SUM(I9*7%),2) -> 437.53 | K9: =ROUND(SUM(H9*I9),2) -> 6250.47 | L9: 500 | M9: Credit Card | N9: Cat | O9: 0 | P9: Tax Invoice | Q9: =IF(B9=B8,Q8+1,1) -> 2 | R9: =SUMIF($B$2:$K$500,S9,$K$2:$K$500) -> 715.89 | S9: 505008 | T9: =R9*1.07 -> 766.0023
A10: 45417 | B10: 505004 | C10: A106 | D10: 4892210180988-BF | E10: =IFERROR(VLOOKUP(D10,ProductMaster!$A:$B,2,FALSE),"") -> 001998236DG9-(BF) | F10: =IFERROR(VLOOKUP(D10,ProductMaster!$A:$C,3,FALSE),"") -> M18HB8ASIA-(BF) | G10: =IFERROR(VLOOKUP($D10,ProductMaster!$A:$O,4,FALSE),"") -> แบตเตอรี่ 18 โวลต์ 8.0 แอมป์อาว HIGH OUTPUT | H10: 1 | I10: =IFERROR(VLOOKUP(E10,ProductMaster!B:G,6,FALSE),0) -> 3542.0561 | J10: =ROUND(SUM(I10*7%),2) -> 247.94 | K10: =ROUND(SUM(H10*I10),2) -> 3542.06 | M10: Credit Card | N10: Cat | O10: 0 | P10: Tax Invoice | Q10: =IF(B10=B9,Q9+1,1) -> 3 | R10: =SUMIF($B$2:$K$500,S10,$K$2:$K$500) -> 287.85 | S10: 505009 | T10: =R10*1.07 -> 307.9995
A11: 45417 | B11: 505005 | C11: A106 | D11: 4892210205896 | E11: =IFERROR(VLOOKUP(D11,ProductMaster!$A:$B,2,FALSE),"") -> 018521012 | F11: =IFERROR(VLOOKUP(D11,ProductMaster!$A:$C,3,FALSE),"") -> M18 FSAGV100XPDB-0X0 ASIA | G11: =IFERROR(VLOOKUP($D11,ProductMaster!$A:$O,4,FALSE),"") -> M18 FUEL GEN II 100MM VARIABLE SPEED BRAKING ANGLE GRINDER,P | H11: 1 | I11: =IFERROR(VLOOKUP(E11,ProductMaster!B:G,6,FALSE),0) -> 6624.2991 | J11: =ROUND(SUM(I11*7%),2) -> 463.7 | K11: =ROUND(SUM(H11*I11),2) -> 6624.3 | L11: 500 | M11: Credit Card | N11: Cat | O11: 0 | P11: Tax Invoice | Q11: =IF(B11=B10,Q10+1,1) -> 1 | R11: =SUMIF($B$2:$K$500,S11,$K$2:$K$500) -> 2783.18 | S11: 505010 | T11: =R11*1.07 -> 2978.0026
A12: 45417 | B12: 505006 | C12: Onetime | D12: 45242509171 | E12: =IFERROR(VLOOKUP(D12,ProductMaster!$A:$B,2,FALSE),"") -> 006067501 | F12: =IFERROR(VLOOKUP(D12,ProductMaster!$A:$C,3,FALSE),"") -> 48-22-8901 | G12: =IFERROR(VLOOKUP($D12,ProductMaster!$A:$O,4,FALSE),"") -> ถุงมือกันบาด Cut 1 Dipped Gloves - M | H12: 1 | I12: =IFERROR(VLOOKUP(E12,ProductMaster!B:G,6,FALSE),0) -> 157.00935 | J12: =ROUND(SUM(I12*7%),2) -> 10.99 | K12: =ROUND(SUM(H12*I12),2) -> 157.01 | M12: Cash | N12: Cat | O12: 0 | P12: No Tax Invoice | Q12: =IF(B12=B11,Q11+1,1) -> 1 | R12: =SUMIF($B$2:$K$500,S12,$K$2:$K$500) -> 82.24 | S12: 505011 | T12: =R12*1.07 -> 87.9968
A13: 45417 | B13: 505006 | C13: Onetime | D13: 45242268061 | E13: =IFERROR(VLOOKUP(D13,ProductMaster!$A:$B,2,FALSE),"") -> 129226207 | F13: =IFERROR(VLOOKUP(D13,ProductMaster!$A:$C,3,FALSE),"") -> 48-22-1905 | G13: =IFERROR(VLOOKUP($D13,ProductMaster!$A:$O,4,FALSE),"") -> ใบมีดอเนกประสงค์ 5ใบ | H13: 1 | I13: =IFERROR(VLOOKUP(E13,ProductMaster!B:G,6,FALSE),0) -> 82.242991 | J13: =ROUND(SUM(I13*7%),2) -> 5.76 | K13: =ROUND(SUM(H13*I13),2) -> 82.24 | M13: Cash | N13: Cat | O13: 0 | P13: No Tax Invoice | Q13: =IF(B13=B12,Q12+1,1) -> 2 | R13: =SUMIF($B$2:$K$500,S13,$K$2:$K$500) -> 1099.06 | S13: 505012 | T13: =R13*1.07 -> 1175.9942
A14: 45417 | B14: 505007 | C14: Onetime | D14: 45242509188 | E14: =IFERROR(VLOOKUP(D14,ProductMaster!$A:$B,2,FALSE),"") -> 006067601 | F14: =IFERROR(VLOOKUP(D14,ProductMaster!$A:$C,3,FALSE),"") -> 48-22-8902 | G14: =IFERROR(VLOOKUP($D14,ProductMaster!$A:$O,4,FALSE),"") -> ถุงมือกันบาด Cut 1 Dipped Gloves - L | H14: 1 | I14: =IFERROR(VLOOKUP(E14,ProductMaster!B:G,6,FALSE),0) -> 157.00935 | J14: =ROUND(SUM(I14*7%),2) -> 10.99 | K14: =ROUND(SUM(H14*I14),2) -> 157.01 | M14: Cash | N14: Cat | O14: 0 | P14: No Tax Invoice | Q14: =IF(B14=B13,Q13+1,1) -> 1 | R14: =SUMIF($B$2:$K$500,S14,$K$2:$K$500) -> 938.32 | S14: 505013 | T14: =R14*1.07 -> 1004.0024
A15: 45417 | B15: 505007 | C15: Onetime | D15: 45242573912 | E15: =IFERROR(VLOOKUP(D15,ProductMaster!$A:$B,2,FALSE),"") -> 006105507 | F15: =IFERROR(VLOOKUP(D15,ProductMaster!$A:$C,3,FALSE),"") -> 48-22-1505 | G15: =IFERROR(VLOOKUP($D15,ProductMaster!$A:$O,4,FALSE),"") -> มีดพับอเนกประสงค์ พร้อมช่องเก็บใบมีด รุ่น FASTBACK™ 6 IN 1 | H15: 1 | I15: =IFERROR(VLOOKUP(E15,ProductMaster!B:G,6,FALSE),0) -> 699.06542 | J15: =ROUND(SUM(I15*7%),2) -> 48.93 | K15: =ROUND(SUM(H15*I15),2) -> 699.07 | M15: Cash | N15: Cat | O15: 0 | P15: No Tax Invoice | Q15: =IF(B15=B14,Q14+1,1) -> 2 | R15: =SUMIF($B$2:$K$500,S15,$K$2:$K$500) -> 4287.85 | S15: 505014 | T15: =R15*1.07 -> 4587.9995
A16: 45417 | B16: 505008 | C16: Onetime | D16: 45242509287 | E16: =IFERROR(VLOOKUP(D16,ProductMaster!$A:$B,2,FALSE),"") -> 006068601 | F16: =IFERROR(VLOOKUP(D16,ProductMaster!$A:$C,3,FALSE),"") -> 48-22-8952 | G16: =IFERROR(VLOOKUP($D16,ProductMaster!$A:$O,4,FALSE),"") -> ถุงมือกันบาด Cut 5 Dipped Gloves - L | H16: 1 | I16: =IFERROR(VLOOKUP(E16,ProductMaster!B:G,6,FALSE),0) -> 558.8785 | J16: =ROUND(SUM(I16*7%),2) -> 39.12 | K16: =ROUND(SUM(H16*I16),2) -> 558.88 | M16: Transfer | N16: Cat | O16: 0 | P16: No Tax Invoice | Q16: =IF(B16=B15,Q15+1,1) -> 1 | R16: =SUMIF($B$2:$K$500,S16,$K$2:$K$500) -> 829.91 | S16: 505015 | T16: =R16*1.07 -> 888.0037
A17: 45417 | B17: 505008 | C17: Onetime | D17: 45242509188 | E17: =IFERROR(VLOOKUP(D17,ProductMaster!$A:$B,2,FALSE),"") -> 006067601 | F17: =IFERROR(VLOOKUP(D17,ProductMaster!$A:$C,3,FALSE),"") -> 48-22-8902 | G17: =IFERROR(VLOOKUP($D17,ProductMaster!$A:$O,4,FALSE),"") -> ถุงมือกันบาด Cut 1 Dipped Gloves - L | H17: 1 | I17: =IFERROR(VLOOKUP(E17,ProductMaster!B:G,6,FALSE),0) -> 157.00935 | J17: =ROUND(SUM(I17*7%),2) -> 10.99 | K17: =ROUND(SUM(H17*I17),2) -> 157.01 | M17: Transfer | N17: Cat | O17: 0 | P17: No Tax Invoice | Q17: =IF(B17=B16,Q16+1,1) -> 2 | R17: =SUMIF($B$2:$K$500,S17,$K$2:$K$500) -> 25403.74 | S17: 505016 | T17: =R17*1.07 -> 27182.002
A18: 45417 | B18: 505009 | C18: Onetime | D18: 45242502691 | E18: =IFERROR(VLOOKUP(D18,ProductMaster!$A:$B,2,FALSE),"") -> 076002284 | F18: =IFERROR(VLOOKUP(D18,ProductMaster!$A:$C,3,FALSE),"") -> 48-22-7816 | G18: =IFERROR(VLOOKUP($D18,ProductMaster!$A:$O,4,FALSE),"") -> ตลับเมตรรุ่น RED 5 เมตร/16 ฟุต | H18: 1 | I18: =IFERROR(VLOOKUP(E18,ProductMaster!B:G,6,FALSE),0) -> 287.85047 | J18: =ROUND(SUM(I18*7%),2) -> 20.15 | K18: =ROUND(SUM(H18*I18),2) -> 287.85 | M18: Transfer | N18: Cat | O18: 0 | P18: No Tax Invoice | Q18: =IF(B18=B17,Q17+1,1) -> 1 | R18: =SUMIF($B$2:$K$500,S18,$K$2:$K$500) -> 818.7 | S18: 505017 | T18: =R18*1.07 -> 876.009
A19: 45417 | B19: 505010 | C19: Onetime | D19: 4892210220677-BF | E19: =IFERROR(VLOOKUP(D19,ProductMaster!$A:$B,2,FALSE),"") -> 001997033-(BF) | F19: =IFERROR(VLOOKUP(D19,ProductMaster!$A:$C,3,FALSE),"") -> M12HB5-(BF) | G19: =IFERROR(VLOOKUP($D19,ProductMaster!$A:$O,4,FALSE),"") -> แบตเตอรี่ 12 โวลต์ 5.0 แอมป์อาว HIGH OUTPUT | H19: 1 | I19: =IFERROR(VLOOKUP(E19,ProductMaster!B:G,6,FALSE),0) -> 1485.9813 | J19: =ROUND(SUM(I19*7%),2) -> 104.02 | K19: =ROUND(SUM(H19*I19),2) -> 1485.98 | M19: Transfer | N19: Cat | O19: 0 | P19: No Tax Invoice | Q19: =IF(B19=B18,Q18+1,1) -> 1 | R19: =SUMIF($B$2:$K$500,S19,$K$2:$K$500) -> 633.64 | S19: 505018 | T19: =R19*1.07 -> 677.9948
A20: 45417 | B20: 505010 | C20: Onetime | D20: 45242505326 | E20: =IFERROR(VLOOKUP(D20,ProductMaster!$A:$B,2,FALSE),"") -> 129305053 | F20: =IFERROR(VLOOKUP(D20,ProductMaster!$A:$C,3,FALSE),"") -> 48-22-8435 | G20: =IFERROR(VLOOKUP($D20,ProductMaster!$A:$O,4,FALSE),"") -> กล่องอุปกรณ์ช่าง PACKOUT Compact Organizer | H20: 1 | I20: =IFERROR(VLOOKUP(E20,ProductMaster!B:G,6,FALSE),0) -> 1297.1963 | J20: =ROUND(SUM(I20*7%),2) -> 90.8 | K20: =ROUND(SUM(H20*I20),2) -> 1297.2 | M20: Transfer | N20: Cat | O20: 0 | P20: No Tax Invoice | Q20: =IF(B20=B19,Q19+1,1) -> 2 | R20: =SUMIF($B$2:$K$500,S20,$K$2:$K$500) -> 60564.5 | S20: 505019 | T20: =R20*1.07 -> 64804.015
A21: 45417 | B21: 505011 | C21: A041 | D21: 45242268061 | E21: =IFERROR(VLOOKUP(D21,ProductMaster!$A:$B,2,FALSE),"") -> 129226207 | F21: =IFERROR(VLOOKUP(D21,ProductMaster!$A:$C,3,FALSE),"") -> 48-22-1905 | G21: =IFERROR(VLOOKUP($D21,ProductMaster!$A:$O,4,FALSE),"") -> ใบมีดอเนกประสงค์ 5ใบ | H21: 1 | I21: =IFERROR(VLOOKUP(E21,ProductMaster!B:G,6,FALSE),0) -> 82.242991 | J21: =ROUND(SUM(I21*7%),2) -> 5.76 | K21: =ROUND(SUM(H21*I21),2) -> 82.24 | M21: Transfer | N21: Cat | O21: 0 | P21: Tax Invoice | Q21: =IF(B21=B20,Q20+1,1) -> 1 | R21: =SUMIF($B$2:$K$500,S21,$K$2:$K$500) -> 8676.63 | S21: 505020 | T21: =R21*1.07 -> 9283.9941 | U21: โอนรวมกับบิล 0505002 ยอด 2,288
A22: 45417 | B22: 505012 | C22: A108 | D22: 45242645701 | E22: =IFERROR(VLOOKUP(D22,ProductMaster!$A:$B,2,FALSE),"") -> 006157301 | F22: =IFERROR(VLOOKUP(D22,ProductMaster!$A:$C,3,FALSE),"") -> 48-22-2184 | G22: =IFERROR(VLOOKUP($D22,ProductMaster!$A:$O,4,FALSE),"") -> ประแจหกเหลี่ยมหัวทอร์คแบบพับเก็บ 8 ชิ้น | H22: 1 | I22: =IFERROR(VLOOKUP(E22,ProductMaster!B:G,6,FALSE),0) -> 549.53271 | J22: =ROUND(SUM(I22*7%),2) -> 38.47 | K22: =ROUND(SUM(H22*I22),2) -> 549.53 | M22: Transfer | N22: Cat | O22: 0 | P22: Tax Invoice | Q22: =IF(B22=B21,Q21+1,1) -> 1 | R22: =SUMIF($B$2:$K$500,S22,$K$2:$K$500) -> 633.64 | S22: 505021 | T22: =R22*1.07 -> 677.9948
A23: 45417 | B23: 505012 | C23: A108 | D23: 45242630585 | E23: =IFERROR(VLOOKUP(D23,ProductMaster!$A:$B,2,FALSE),"") -> 006138701 | F23: =IFERROR(VLOOKUP(D23,ProductMaster!$A:$C,3,FALSE),"") -> 48-22-2182 | G23: =IFERROR(VLOOKUP($D23,ProductMaster!$A:$O,4,FALSE),"") -> ประแจหกเหลี่ยมแบบพับเก็บ 8 ชิ้น | H23: 1 | I23: =IFERROR(VLOOKUP(E23,ProductMaster!B:G,6,FALSE),0) -> 549.53271 | J23: =ROUND(SUM(I23*7%),2) -> 38.47 | K23: =ROUND(SUM(H23*I23),2) -> 549.53 | M23: Transfer | N23: Cat | O23: 0 | P23: Tax Invoice | Q23: =IF(B23=B22,Q22+1,1) -> 2 | R23: =SUMIF($B$2:$K$500,S23,$K$2:$K$500) -> 633.64 | S23: 505022 | T23: =R23*1.07 -> 677.9948
A24: 45417 | B24: 505013 | C24: Onetime | D24: 45242534395 | E24: =IFERROR(VLOOKUP(D24,ProductMaster!$A:$B,2,FALSE),"") -> 006084404 | F24: =IFERROR(VLOOKUP(D24,ProductMaster!$A:$C,3,FALSE),"") -> 48-22-1906 | G24: =IFERROR(VLOOKUP($D24,ProductMaster!$A:$O,4,FALSE),"") -> มีดพับคอมแพ็คอเนกประสงค์ | H24: 1 | I24: =IFERROR(VLOOKUP(E24,ProductMaster!B:G,6,FALSE),0) -> 446.72897 | J24: =ROUND(SUM(I24*7%),2) -> 31.27 | K24: =ROUND(SUM(H24*I24),2) -> 446.73 | M24: Cash | N24: Cat | O24: 0 | P24: No Tax Invoice | Q24: =IF(B24=B23,Q23+1,1) -> 1 | R24: =SUMIF($B$2:$K$500,S24,$K$2:$K$500) -> 2390.65 | S24: 505023 | T24: =R24*1.07 -> 2557.9955
A25: 45417 | B25: 505013 | C25: Onetime | D25: 45242268061 | E25: =IFERROR(VLOOKUP(D25,ProductMaster!$A:$B,2,FALSE),"") -> 129226207 | F25: =IFERROR(VLOOKUP(D25,ProductMaster!$A:$C,3,FALSE),"") -> 48-22-1905 | G25: =IFERROR(VLOOKUP($D25,ProductMaster!$A:$O,4,FALSE),"") -> ใบมีดอเนกประสงค์ 5ใบ | H25: 1 | I25: =IFERROR(VLOOKUP(E25,ProductMaster!B:G,6,FALSE),0) -> 82.242991 | J25: =ROUND(SUM(I25*7%),2) -> 5.76 | K25: =ROUND(SUM(H25*I25),2) -> 82.24 | M25: Cash | N25: Cat | O25: 0 | P25: No Tax Invoice | Q25: =IF(B25=B24,Q24+1,1) -> 2 | R25: =SUMIF($B$2:$K$500,S25,$K$2:$K$500) -> 29555.15 | S25: 505024 | T25: =R25*1.07 -> 31624.011
A26: 45417 | B26: 505013 | C26: Onetime | D26: 45242082834 | E26: =IFERROR(VLOOKUP(D26,ProductMaster!$A:$B,2,FALSE),"") -> 129221226 | F26: =IFERROR(VLOOKUP(D26,ProductMaster!$A:$C,3,FALSE),"") -> 48-00-5182 | G26: =IFERROR(VLOOKUP($D26,ProductMaster!$A:$O,4,FALSE),"") -> ใบเลื่อยซอว์ซอลตัดเหล็ก 6" Thin Kerf 14 TPI (5 ใบ) | H26: 1 | I26: =IFERROR(VLOOKUP(E26,ProductMaster!B:G,6,FALSE),0) -> 409.34579 | J26: =ROUND(SUM(I26*7%),2) -> 28.65 | K26: =ROUND(SUM(H26*I26),2) -> 409.35 | M26: Cash | N26: Cat | O26: 0 | P26: No Tax Invoice | Q26: =IF(B26=B25,Q25+1,1) -> 3 | R26: =SUMIF($B$2:$K$500,S26,$K$2:$K$500) -> 6080.38 | S26: 505025 | T26: =R26*1.07 -> 6506.0066
A27: 45417 | B27: 505014 | C27: Onetime | D27: 45242531684 | E27: =IFERROR(VLOOKUP(D27,ProductMaster!$A:$B,2,FALSE),"") -> 006082201 | F27: =IFERROR(VLOOKUP(D27,ProductMaster!$A:$C,3,FALSE),"") -> 48-22-8301 | G27: =IFERROR(VLOOKUP($D27,ProductMaster!$A:$O,4,FALSE),"") -> เป้สะพายหลังใส่เครื่องมือ PACKOUT Backpack | H27: 1 | I27: =IFERROR(VLOOKUP(E27,ProductMaster!B:G,6,FALSE),0) -> 4287.8505 | J27: =ROUND(SUM(I27*7%),2) -> 300.15 | K27: =ROUND(SUM(H27*I27),2) -> 4287.85 | M27: Credit Card | N27: Cat | O27: 0 | P27: No Tax Invoice | Q27: =IF(B27=B26,Q26+1,1) -> 1 | R27: =SUMIF($B$2:$K$500,S27,$K$2:$K$500) -> 17652.34 | S27: 505026 | T27: =R27*1.07 -> 18888.004
A28: 45417 | B28: 505015 | C28: Onetime | D28: 45242638796 | E28: =IFERROR(VLOOKUP(D28,ProductMaster!$A:$B,2,FALSE),"") -> 006143201 | F28: =IFERROR(VLOOKUP(D28,ProductMaster!$A:$C,3,FALSE),"") -> 48-22-0307 | G28: =IFERROR(VLOOKUP($D28,ProductMaster!$A:$O,4,FALSE),"") -> เลื่อยอเนกประสงค์แบบพับ | H28: 1 | I28: =IFERROR(VLOOKUP(E28,ProductMaster!B:G,6,FALSE),0) -> 829.90654 | J28: =ROUND(SUM(I28*7%),2) -> 58.09 | K28: =ROUND(SUM(H28*I28),2) -> 829.91 | M28: Transfer | N28: Cat | O28: 0 | P28: No Tax Invoice | Q28: =IF(B28=B27,Q27+1,1) -> 1 | R28: =SUMIF($B$2:$K$500,S28,$K$2:$K$500) -> 17652.34 | S28: 505027 | T28: =R28*1.07 -> 18888.004
A29: 45417 | B29: 505016 | C29: Onetime | D29: 4892210196293 | E29: =IFERROR(VLOOKUP(D29,ProductMaster!$A:$B,2,FALSE),"") -> 018508015 | F29: =IFERROR(VLOOKUP(D29,ProductMaster!$A:$C,3,FALSE),"") -> M18 FMTIW2F12-0X0 ASIA | G29: =IFERROR(VLOOKUP($D29,ProductMaster!$A:$O,4,FALSE),"") -> M18 FUEL บล็อกกระแทกไร้สาย 1/2" มิดทอร์ค | H29: 1 | I29: =IFERROR(VLOOKUP(E29,ProductMaster!B:G,6,FALSE),0) -> 7465.4206 | J29: =ROUND(SUM(I29*7%),2) -> 522.58 | K29: =ROUND(SUM(H29*I29),2) -> 7465.42 | M29: Credit Card | N29: Cat | O29: 0 | P29: No Tax Invoice | Q29: =IF(B29=B28,Q28+1,1) -> 1 | R29: =SUMIF($B$2:$K$500,S29,$K$2:$K$500) -> 699.07 | S29: 505028 | T29: =R29*1.07 -> 748.0049
A30: 45417 | B30: 505016 | C30: Onetime | D30: 4892210222107 | E30: =IFERROR(VLOOKUP(D30,ProductMaster!$A:$B,2,FALSE),"") -> 018677003 | F30: =IFERROR(VLOOKUP(D30,ProductMaster!$A:$C,3,FALSE),"") -> M18 FHS20-0B0 ASIA | G30: =IFERROR(VLOOKUP($D30,ProductMaster!$A:$O,4,FALSE),"") -> M18 FUEL เลื่อยโซ่ 8” | H30: 1 | I30: =IFERROR(VLOOKUP(E30,ProductMaster!B:G,6,FALSE),0) -> 9334.5794 | J30: =ROUND(SUM(I30*7%),2) -> 653.42 | K30: =ROUND(SUM(H30*I30),2) -> 9334.58 | M30: Credit Card | N30: Cat | O30: 0 | P30: No Tax Invoice | Q30: =IF(B30=B29,Q29+1,1) -> 2 | R30: =SUMIF($B$2:$K$500,S30,$K$2:$K$500) -> 586.92 | S30: 505029 | T30: =R30*1.07 -> 628.0044
A31: 45417 | B31: 505016 | C31: Onetime | D31: 4892210180988-BF | E31: =IFERROR(VLOOKUP(D31,ProductMaster!$A:$B,2,FALSE),"") -> 001998236DG9-(BF) | F31: =IFERROR(VLOOKUP(D31,ProductMaster!$A:$C,3,FALSE),"") -> M18HB8ASIA-(BF) | G31: =IFERROR(VLOOKUP($D31,ProductMaster!$A:$O,4,FALSE),"") -> แบตเตอรี่ 18 โวลต์ 8.0 แอมป์อาว HIGH OUTPUT | H31: 1 | I31: =IFERROR(VLOOKUP(E31,ProductMaster!B:G,6,FALSE),0) -> 3542.0561 | J31: =ROUND(SUM(I31*7%),2) -> 247.94 | K31: =ROUND(SUM(H31*I31),2) -> 3542.06 | L31: 500 | M31: Credit Card | N31: Cat | O31: 0 | P31: No Tax Invoice | Q31: =IF(B31=B30,Q30+1,1) -> 3 | R31: =SUMIF($B$2:$K$500,S31,$K$2:$K$500) -> 10175.7 | S31: 505030 | T31: =R31*1.07 -> 10887.999
A32: 45417 | B32: 505016 | C32: Onetime | D32: 4892210141347-BF | E32: =IFERROR(VLOOKUP(D32,ProductMaster!$A:$B,2,FALSE),"") -> 001998238-(BF) | F32: =IFERROR(VLOOKUP(D32,ProductMaster!$A:$C,3,FALSE),"") -> M18B5ASIA-(BF) | G32: =IFERROR(VLOOKUP($D32,ProductMaster!$A:$O,4,FALSE),"") -> แบตเตอรี่ 18 โวลต์ 5.0 แอมป์อาว | H32: 1 | I32: =IFERROR(VLOOKUP(E32,ProductMaster!B:G,6,FALSE),0) -> 1859.8131 | J32: =ROUND(SUM(I32*7%),2) -> 130.19 | K32: =ROUND(SUM(H32*I32),2) -> 1859.81 | M32: Credit Card | N32: Cat | O32: 0 | P32: No Tax Invoice | Q32: =IF(B32=B31,Q31+1,1) -> 4 | R32: =SUMIF($B$2:$K$500,S32,$K$2:$K$500) -> 287.85 | S32: 505031 | T32: =R32*1.07 -> 307.9995
A33: 45417 | B33: 505016 | C33: Onetime | D33: 4892210139313-BF | E33: =IFERROR(VLOOKUP(D33,ProductMaster!$A:$B,2,FALSE),"") -> 001997014-(BF) | F33: =IFERROR(VLOOKUP(D33,ProductMaster!$A:$C,3,FALSE),"") -> M12-18FCSA-(BF) | G33: =IFERROR(VLOOKUP($D33,ProductMaster!$A:$O,4,FALSE),"") -> แท่นชาร์จแบตเตอรี่ 12-18 โวลต์ แบบชาร์จเร็ว | H33: 1 | I33: =IFERROR(VLOOKUP(E33,ProductMaster!B:G,6,FALSE),0) -> 1766.3551 | J33: =ROUND(SUM(I33*7%),2) -> 123.64 | K33: =ROUND(SUM(H33*I33),2) -> 1766.36 | M33: Credit Card | N33: Cat | O33: 0 | P33: No Tax Invoice | Q33: =IF(B33=B32,Q32+1,1) -> 5 | R33: =SUMIF($B$2:$K$500,S33,$K$2:$K$500) -> 633.64 | S33: 505032 | T33: =R33*1.07 -> 677.9948
A34: 45417 | B34: 505016 | C34: Onetime | D34: 4058546404611 | E34: =IFERROR(VLOOKUP(D34,ProductMaster!$A:$B,2,FALSE),"") -> 001998668 | F34: =IFERROR(VLOOKUP(D34,ProductMaster!$A:$C,3,FALSE),"") -> 4932480176 | G34: =IFERROR(VLOOKUP($D34,ProductMaster!$A:$O,4,FALSE),"") -> โซ่เลื่อย 8" สำหรับ M18 FHS | H34: 1 | I34: =IFERROR(VLOOKUP(E34,ProductMaster!B:G,6,FALSE),0) -> 801.86916 | J34: =ROUND(SUM(I34*7%),2) -> 56.13 | K34: =ROUND(SUM(H34*I34),2) -> 801.87 | M34: Credit Card | N34: Cat | O34: 0 | P34: No Tax Invoice | Q34: =IF(B34=B33,Q33+1,1) -> 6 | R34: =SUMIF($B$2:$K$500,S34,$K$2:$K$500) -> 18706.55 | S34: 505033 | T34: =R34*1.07 -> 20016.009
